2017-10-06 01:41:22.514572 WARNING ------------------------------------------------------------
2017-10-06 01:41:22.517510 WARNING Unexpected error in worker for App Alarm:
2017-10-06 01:41:22.520953 WARNING Worker Ags: {'id': UUID('3917c45f-4371-4d17-9d75-a834abec83bc'), 'data': {'old_state': {'last_updated': '2017-10-05T23:41:08.595921+00:00', 'entity_id': 'alarm_control_panel.house', 'attributes': {'friendly_name': 'House', 'immediate': ['binary_sensor.door_window_sensor_158d000187120a'], 'zones': ['group.zone_downstairs', 'group.zone_garage', 'group.zone_kitchen', 'group.zone_living_room', 'group.zone_outside', 'group.zone_upstairs'], 'changed_by': '', 'ignored': ['binary_sensor.motion_sensor_158d00016dcfa8'], 'bypassedsensors': [], 'code_format': None, 'triggeredBy': "{'name': 'Rajen', 'chat_id': '346686450'}", 'delayed': ['binary_sensor.switch_158d000186e9bd'], 'changedby': '', 'trippedsensors': [], 'allsensors': ['binary_sensor.door_window_sensor_158d000187120a', 'binary_sensor.motion_sensor_158d00016dcfa8', 'binary_sensor.switch_158d000186e9bd']}, 'state': 'armed_home', 'last_changed': '2017-10-05T23:41:08.595921+00:00'}, 'entity_id': 'alarm_control_panel.house', 'new_state': {'last_updated': '2017-10-05T23:41:20.340940+00:00', 'entity_id': 'alarm_control_panel.house', 'attributes': {'friendly_name': 'House', 'immediate': ['binary_sensor.door_window_sensor_158d000187120a'], 'zones': ['group.zone_downstairs', 'group.zone_garage', 'group.zone_kitchen', 'group.zone_living_room', 'group.zone_outside', 'group.zone_upstairs'], 'changed_by': '', 'ignored': ['binary_sensor.motion_sensor_158d00016dcfa8'], 'bypassedsensors': [], 'code_format': None, 'triggeredBy': None, 'delayed': ['binary_sensor.switch_158d000186e9bd'], 'changedby': '', 'trippedsensors': [], 'allsensors': ['binary_sensor.door_window_sensor_158d000187120a', 'binary_sensor.motion_sensor_158d00016dcfa8', 'binary_sensor.switch_158d000186e9bd']}, 'state': 'triggered', 'last_changed': '2017-10-05T23:41:20.340940+00:00'}}, 'name': 'Alarm', 'function': <bound method AlarmReaction.alarmListener of <alarm.AlarmReaction object at 0xb5b306d0>>, 'type': 'event', 'event': 'state_changed', 'kwargs': {'entity_id': 'alarm_control_panel.house'}}
2017-10-06 01:41:22.523672 WARNING ------------------------------------------------------------
2017-10-06 01:41:22.613258 WARNING Traceback (most recent call last):
  File "/srv/homeassistant/lib/python3.4/site-packages/appdaemon/appdaemon.py", line 528, in worker
    function(args["event"], data, args["kwargs"])
  File "/home/homeassistant/config/appdaemon/apps/alarm.py", line 17, in alarmListener
    self.trigger(data,kwargs)
  File "/home/homeassistant/config/appdaemon/apps/alarm.py", line 26, in trigger
    triggered_by = self.getTriggeredBy(data)
  File "/home/homeassistant/config/appdaemon/apps/alarm.py", line 36, in getTriggeredBy
    triggered_by = {'name': self.friendly_name(data['new_state']['attributes']['changedby'])}
  File "/srv/homeassistant/lib/python3.4/site-packages/appdaemon/appapi.py", line 186, in friendly_name
    self._check_entity(entity_id)
  File "/srv/homeassistant/lib/python3.4/site-packages/appdaemon/appapi.py", line 140, in _check_entity
    "{}: Invalid entity ID: {}".format(self.name, entity))
ValueError: Alarm: Invalid entity ID: 

2017-10-06 01:41:22.622724 WARNING ------------------------------------------------------------
2017-10-06 01:46:41.033549 WARNING ------------------------------------------------------------
2017-10-06 01:46:41.038272 WARNING Unexpected error in worker for App Telegram:
2017-10-06 01:46:41.042463 WARNING Worker Ags: {'id': UUID('51358756-a0b5-4beb-8f83-d5320d02a304'), 'type': 'timer', 'name': 'Telegram', 'function': None, 'kwargs': {}}
2017-10-06 01:46:41.046392 WARNING ------------------------------------------------------------
2017-10-06 01:46:41.051710 WARNING Traceback (most recent call last):
  File "/srv/homeassistant/lib/python3.4/site-packages/appdaemon/appdaemon.py", line 518, in worker
    function(ha.sanitize_timer_kwargs(args["kwargs"]))
TypeError: 'NoneType' object is not callable

2017-10-06 01:46:41.055779 WARNING ------------------------------------------------------------
2017-10-06 01:46:47.032658 WARNING ------------------------------------------------------------
2017-10-06 01:46:47.037292 WARNING Unexpected error in worker for App Telegram:
2017-10-06 01:46:47.044531 WARNING Worker Ags: {'id': UUID('51358756-a0b5-4beb-8f83-d5320d02a304'), 'type': 'timer', 'name': 'Telegram', 'function': None, 'kwargs': {}}
2017-10-06 01:46:47.050918 WARNING ------------------------------------------------------------
2017-10-06 01:46:47.059623 WARNING Traceback (most recent call last):
  File "/srv/homeassistant/lib/python3.4/site-packages/appdaemon/appdaemon.py", line 518, in worker
    function(ha.sanitize_timer_kwargs(args["kwargs"]))
TypeError: 'NoneType' object is not callable

2017-10-06 01:46:47.065600 WARNING ------------------------------------------------------------
2017-10-06 01:46:53.038772 WARNING ------------------------------------------------------------
2017-10-06 01:46:53.043369 WARNING Unexpected error in worker for App Telegram:
2017-10-06 01:46:53.051206 WARNING Worker Ags: {'id': UUID('51358756-a0b5-4beb-8f83-d5320d02a304'), 'type': 'timer', 'name': 'Telegram', 'function': None, 'kwargs': {}}
2017-10-06 01:46:53.056601 WARNING ------------------------------------------------------------
2017-10-06 01:46:53.063725 WARNING Traceback (most recent call last):
  File "/srv/homeassistant/lib/python3.4/site-packages/appdaemon/appdaemon.py", line 518, in worker
    function(ha.sanitize_timer_kwargs(args["kwargs"]))
TypeError: 'NoneType' object is not callable

2017-10-06 01:46:53.068083 WARNING ------------------------------------------------------------
2017-10-06 01:46:58.031367 WARNING ------------------------------------------------------------
2017-10-06 01:46:58.037077 WARNING Unexpected error in worker for App Telegram:
2017-10-06 01:46:58.044020 WARNING Worker Ags: {'id': UUID('51358756-a0b5-4beb-8f83-d5320d02a304'), 'type': 'timer', 'name': 'Telegram', 'function': None, 'kwargs': {}}
2017-10-06 01:46:58.050241 WARNING ------------------------------------------------------------
2017-10-06 01:46:58.058433 WARNING Traceback (most recent call last):
  File "/srv/homeassistant/lib/python3.4/site-packages/appdaemon/appdaemon.py", line 518, in worker
    function(ha.sanitize_timer_kwargs(args["kwargs"]))
TypeError: 'NoneType' object is not callable

2017-10-06 01:46:58.063067 WARNING ------------------------------------------------------------
2017-10-06 02:16:14.041674 WARNING ------------------------------------------------------------
2017-10-06 02:16:14.045971 WARNING Unexpected error in worker for App Telegram:
2017-10-06 02:16:14.049811 WARNING Worker Ags: {'id': UUID('51358756-a0b5-4beb-8f83-d5320d02a304'), 'type': 'timer', 'name': 'Telegram', 'function': None, 'kwargs': {}}
2017-10-06 02:16:14.053445 WARNING ------------------------------------------------------------
2017-10-06 02:16:14.059248 WARNING Traceback (most recent call last):
  File "/srv/homeassistant/lib/python3.4/site-packages/appdaemon/appdaemon.py", line 518, in worker
    function(ha.sanitize_timer_kwargs(args["kwargs"]))
TypeError: 'NoneType' object is not callable

2017-10-06 02:16:14.062837 WARNING ------------------------------------------------------------
2017-10-06 02:16:26.032550 WARNING ------------------------------------------------------------
2017-10-06 02:16:26.036610 WARNING Unexpected error in worker for App Telegram:
2017-10-06 02:16:26.040404 WARNING Worker Ags: {'id': UUID('51358756-a0b5-4beb-8f83-d5320d02a304'), 'type': 'timer', 'name': 'Telegram', 'function': None, 'kwargs': {}}
2017-10-06 02:16:26.044168 WARNING ------------------------------------------------------------
2017-10-06 02:16:26.048886 WARNING Traceback (most recent call last):
  File "/srv/homeassistant/lib/python3.4/site-packages/appdaemon/appdaemon.py", line 518, in worker
    function(ha.sanitize_timer_kwargs(args["kwargs"]))
TypeError: 'NoneType' object is not callable

2017-10-06 02:16:26.052875 WARNING ------------------------------------------------------------
2017-10-06 02:59:54.040188 WARNING ------------------------------------------------------------
2017-10-06 02:59:54.044912 WARNING Unexpected error in worker for App Telegram:
2017-10-06 02:59:54.053042 WARNING Worker Ags: {'id': UUID('9203db91-85e9-434f-85ff-bbf5226ed590'), 'type': 'timer', 'name': 'Telegram', 'function': None, 'kwargs': {}}
2017-10-06 02:59:54.059368 WARNING ------------------------------------------------------------
2017-10-06 02:59:54.067837 WARNING Traceback (most recent call last):
  File "/srv/homeassistant/lib/python3.4/site-packages/appdaemon/appdaemon.py", line 518, in worker
    function(ha.sanitize_timer_kwargs(args["kwargs"]))
TypeError: 'NoneType' object is not callable

2017-10-06 02:59:54.072601 WARNING ------------------------------------------------------------
2017-10-06 03:06:58.067314 WARNING ------------------------------------------------------------
2017-10-06 03:06:58.071928 WARNING Unexpected error during loading of telegram.py:
2017-10-06 03:06:58.075974 WARNING ------------------------------------------------------------
2017-10-06 03:06:58.094681 WARNING Traceback (most recent call last):
  File "/srv/homeassistant/lib/python3.4/site-packages/appdaemon/appdaemon.py", line 903, in read_app
    importlib.reload(conf.modules[module_name])
  File "/srv/homeassistant/lib/python3.4/importlib/__init__.py", line 149, in reload
    methods.exec(module)
  File "<frozen importlib._bootstrap>", line 1153, in exec
  File "<frozen importlib._bootstrap>", line 1129, in _exec
  File "<frozen importlib._bootstrap>", line 1467, in exec_module
  File "<frozen importlib._bootstrap>", line 1572, in get_code
  File "<frozen importlib._bootstrap>", line 1532, in source_to_code
  File "<frozen importlib._bootstrap>", line 321, in _call_with_frames_removed
  File "/home/homeassistant/config/appdaemon/apps/telegram.py", line 186
    self.log(handle)
                   ^
TabError: inconsistent use of tabs and spaces in indentation

2017-10-06 03:06:58.099662 WARNING ------------------------------------------------------------
2017-10-06 03:07:03.075884 WARNING ------------------------------------------------------------
2017-10-06 03:07:03.081295 WARNING Unexpected error during loading of telegram.py:
2017-10-06 03:07:03.086541 WARNING ------------------------------------------------------------
2017-10-06 03:07:03.096846 WARNING Traceback (most recent call last):
  File "/srv/homeassistant/lib/python3.4/site-packages/appdaemon/appdaemon.py", line 903, in read_app
    importlib.reload(conf.modules[module_name])
  File "/srv/homeassistant/lib/python3.4/importlib/__init__.py", line 149, in reload
    methods.exec(module)
  File "<frozen importlib._bootstrap>", line 1153, in exec
  File "<frozen importlib._bootstrap>", line 1129, in _exec
  File "<frozen importlib._bootstrap>", line 1467, in exec_module
  File "<frozen importlib._bootstrap>", line 1572, in get_code
  File "<frozen importlib._bootstrap>", line 1532, in source_to_code
  File "<frozen importlib._bootstrap>", line 321, in _call_with_frames_removed
  File "/home/homeassistant/config/appdaemon/apps/telegram.py", line 186
    self.log(handle)
                   ^
TabError: inconsistent use of tabs and spaces in indentation

2017-10-06 03:07:03.101613 WARNING ------------------------------------------------------------
2017-10-06 03:07:14.145149 WARNING ------------------------------------------------------------
2017-10-06 03:07:14.150227 WARNING Unexpected error during loading of telegram.py:
2017-10-06 03:07:14.157928 WARNING ------------------------------------------------------------
2017-10-06 03:07:14.173080 WARNING Traceback (most recent call last):
  File "/srv/homeassistant/lib/python3.4/site-packages/appdaemon/appdaemon.py", line 903, in read_app
    importlib.reload(conf.modules[module_name])
  File "/srv/homeassistant/lib/python3.4/importlib/__init__.py", line 149, in reload
    methods.exec(module)
  File "<frozen importlib._bootstrap>", line 1153, in exec
  File "<frozen importlib._bootstrap>", line 1129, in _exec
  File "<frozen importlib._bootstrap>", line 1471, in exec_module
  File "<frozen importlib._bootstrap>", line 321, in _call_with_frames_removed
  File "/home/homeassistant/config/appdaemon/apps/telegram.py", line 56, in <module>
    class TelegramBotEventListener(appapi.AppDaemon):
  File "/home/homeassistant/config/appdaemon/apps/telegram.py", line 187, in TelegramBotEventListener
    self.run_in(self.bypass(payload_event,accessgroup),5)
NameError: name 'self' is not defined

2017-10-06 03:07:14.179139 WARNING ------------------------------------------------------------
2017-10-06 03:07:33.141968 WARNING ------------------------------------------------------------
2017-10-06 03:07:33.147885 WARNING Unexpected error during loading of telegram.py:
2017-10-06 03:07:33.153454 WARNING ------------------------------------------------------------
2017-10-06 03:07:33.168445 WARNING Traceback (most recent call last):
  File "/srv/homeassistant/lib/python3.4/site-packages/appdaemon/appdaemon.py", line 903, in read_app
    importlib.reload(conf.modules[module_name])
  File "/srv/homeassistant/lib/python3.4/importlib/__init__.py", line 149, in reload
    methods.exec(module)
  File "<frozen importlib._bootstrap>", line 1153, in exec
  File "<frozen importlib._bootstrap>", line 1129, in _exec
  File "<frozen importlib._bootstrap>", line 1471, in exec_module
  File "<frozen importlib._bootstrap>", line 321, in _call_with_frames_removed
  File "/home/homeassistant/config/appdaemon/apps/telegram.py", line 56, in <module>
    class TelegramBotEventListener(appapi.AppDaemon):
  File "/home/homeassistant/config/appdaemon/apps/telegram.py", line 187, in TelegramBotEventListener
    self.run_in(self.bypass(payload_event,accessgroup),5)
NameError: name 'self' is not defined

2017-10-06 03:07:33.173956 WARNING ------------------------------------------------------------
2017-10-06 03:08:20.142305 WARNING ------------------------------------------------------------
2017-10-06 03:08:20.147368 WARNING Unexpected error during loading of telegram.py:
2017-10-06 03:08:20.151202 WARNING ------------------------------------------------------------
2017-10-06 03:08:20.167563 WARNING Traceback (most recent call last):
  File "/srv/homeassistant/lib/python3.4/site-packages/appdaemon/appdaemon.py", line 903, in read_app
    importlib.reload(conf.modules[module_name])
  File "/srv/homeassistant/lib/python3.4/importlib/__init__.py", line 149, in reload
    methods.exec(module)
  File "<frozen importlib._bootstrap>", line 1153, in exec
  File "<frozen importlib._bootstrap>", line 1129, in _exec
  File "<frozen importlib._bootstrap>", line 1471, in exec_module
  File "<frozen importlib._bootstrap>", line 321, in _call_with_frames_removed
  File "/home/homeassistant/config/appdaemon/apps/telegram.py", line 56, in <module>
    class TelegramBotEventListener(appapi.AppDaemon):
  File "/home/homeassistant/config/appdaemon/apps/telegram.py", line 187, in TelegramBotEventListener
    self.run_in(self.bypass(payload_event,accessgroup),5)
NameError: name 'self' is not defined

2017-10-06 03:08:20.175986 WARNING ------------------------------------------------------------
2017-10-06 03:08:22.141404 WARNING ------------------------------------------------------------
2017-10-06 03:08:22.147272 WARNING Unexpected error during loading of telegram.py:
2017-10-06 03:08:22.152586 WARNING ------------------------------------------------------------
2017-10-06 03:08:22.168649 WARNING Traceback (most recent call last):
  File "/srv/homeassistant/lib/python3.4/site-packages/appdaemon/appdaemon.py", line 903, in read_app
    importlib.reload(conf.modules[module_name])
  File "/srv/homeassistant/lib/python3.4/importlib/__init__.py", line 149, in reload
    methods.exec(module)
  File "<frozen importlib._bootstrap>", line 1153, in exec
  File "<frozen importlib._bootstrap>", line 1129, in _exec
  File "<frozen importlib._bootstrap>", line 1471, in exec_module
  File "<frozen importlib._bootstrap>", line 321, in _call_with_frames_removed
  File "/home/homeassistant/config/appdaemon/apps/telegram.py", line 56, in <module>
    class TelegramBotEventListener(appapi.AppDaemon):
  File "/home/homeassistant/config/appdaemon/apps/telegram.py", line 187, in TelegramBotEventListener
    self.run_in(self.bypass(payload_event,accessgroup),5)
NameError: name 'self' is not defined

2017-10-06 03:08:22.175022 WARNING ------------------------------------------------------------
2017-10-06 03:08:27.149979 WARNING ------------------------------------------------------------
2017-10-06 03:08:27.155516 WARNING Unexpected error during loading of telegram.py:
2017-10-06 03:08:27.161858 WARNING ------------------------------------------------------------
2017-10-06 03:08:27.176773 WARNING Traceback (most recent call last):
  File "/srv/homeassistant/lib/python3.4/site-packages/appdaemon/appdaemon.py", line 903, in read_app
    importlib.reload(conf.modules[module_name])
  File "/srv/homeassistant/lib/python3.4/importlib/__init__.py", line 149, in reload
    methods.exec(module)
  File "<frozen importlib._bootstrap>", line 1153, in exec
  File "<frozen importlib._bootstrap>", line 1129, in _exec
  File "<frozen importlib._bootstrap>", line 1471, in exec_module
  File "<frozen importlib._bootstrap>", line 321, in _call_with_frames_removed
  File "/home/homeassistant/config/appdaemon/apps/telegram.py", line 56, in <module>
    class TelegramBotEventListener(appapi.AppDaemon):
  File "/home/homeassistant/config/appdaemon/apps/telegram.py", line 187, in TelegramBotEventListener
    self.run_in(bypass(payload_event,accessgroup),5)
NameError: name 'self' is not defined

2017-10-06 03:08:27.182746 WARNING ------------------------------------------------------------
2017-10-06 03:08:50.205552 WARNING ------------------------------------------------------------
2017-10-06 03:08:50.213811 WARNING Unexpected error in worker for App Telegram:
2017-10-06 03:08:50.222568 WARNING Worker Ags: {'id': UUID('80a18d92-67a8-4a29-9075-805e06611d07'), 'data': {'from_first': 'Legendary', 'from_last': 'Dav', 'text': 'unbypass downstairs', 'user_id': 396287366, 'chat_id': 396287366}, 'name': 'Telegram', 'function': <bound method TelegramBotEventListener.receive_telegram_text of <telegram.TelegramBotEventListener object at 0xb5ae3fd0>>, 'type': 'event', 'event': 'telegram_text', 'kwargs': {}}
2017-10-06 03:08:50.236123 WARNING ------------------------------------------------------------
2017-10-06 03:08:50.249783 WARNING Traceback (most recent call last):
  File "/srv/homeassistant/lib/python3.4/site-packages/appdaemon/appdaemon.py", line 528, in worker
    function(args["event"], data, args["kwargs"])
  File "/home/homeassistant/config/appdaemon/apps/telegram.py", line 107, in receive_telegram_text
    self.bypassZone(payload_event, accessgroup)
  File "/home/homeassistant/config/appdaemon/apps/telegram.py", line 187, in bypassZone
    self.run_in(bypass(payload_event,accessgroup),5)
NameError: name 'bypass' is not defined

2017-10-06 03:08:50.262107 WARNING ------------------------------------------------------------
2017-10-06 03:09:15.032900 WARNING ------------------------------------------------------------
2017-10-06 03:09:15.037768 WARNING Unexpected error in worker for App Telegram:
2017-10-06 03:09:15.041914 WARNING Worker Ags: {'id': UUID('c31c6ae0-fc11-49f4-9b75-9a452d09b0b2'), 'type': 'timer', 'name': 'Telegram', 'function': None, 'kwargs': {}}
2017-10-06 03:09:15.051060 WARNING ------------------------------------------------------------
2017-10-06 03:09:15.057443 WARNING Traceback (most recent call last):
  File "/srv/homeassistant/lib/python3.4/site-packages/appdaemon/appdaemon.py", line 518, in worker
    function(ha.sanitize_timer_kwargs(args["kwargs"]))
TypeError: 'NoneType' object is not callable

2017-10-06 03:09:15.063700 WARNING ------------------------------------------------------------
2017-10-06 03:09:48.032894 WARNING ------------------------------------------------------------
2017-10-06 03:09:48.037763 WARNING Unexpected error in worker for App Telegram:
2017-10-06 03:09:48.045650 WARNING Worker Ags: {'id': UUID('c31c6ae0-fc11-49f4-9b75-9a452d09b0b2'), 'type': 'timer', 'name': 'Telegram', 'function': None, 'kwargs': {}}
2017-10-06 03:09:48.050841 WARNING ------------------------------------------------------------
2017-10-06 03:09:48.060509 WARNING Traceback (most recent call last):
  File "/srv/homeassistant/lib/python3.4/site-packages/appdaemon/appdaemon.py", line 518, in worker
    function(ha.sanitize_timer_kwargs(args["kwargs"]))
TypeError: 'NoneType' object is not callable

2017-10-06 03:09:48.065047 WARNING ------------------------------------------------------------
2017-10-06 03:10:05.032714 WARNING ------------------------------------------------------------
2017-10-06 03:10:05.037544 WARNING Unexpected error in worker for App Telegram:
2017-10-06 03:10:05.045359 WARNING Worker Ags: {'id': UUID('c31c6ae0-fc11-49f4-9b75-9a452d09b0b2'), 'type': 'timer', 'name': 'Telegram', 'function': None, 'kwargs': {}}
2017-10-06 03:10:05.051508 WARNING ------------------------------------------------------------
2017-10-06 03:10:05.059982 WARNING Traceback (most recent call last):
  File "/srv/homeassistant/lib/python3.4/site-packages/appdaemon/appdaemon.py", line 518, in worker
    function(ha.sanitize_timer_kwargs(args["kwargs"]))
TypeError: 'NoneType' object is not callable

2017-10-06 03:10:05.064847 WARNING ------------------------------------------------------------
2017-10-06 03:10:21.033113 WARNING ------------------------------------------------------------
2017-10-06 03:10:21.037923 WARNING Unexpected error in worker for App Telegram:
2017-10-06 03:10:21.045220 WARNING Worker Ags: {'id': UUID('c31c6ae0-fc11-49f4-9b75-9a452d09b0b2'), 'type': 'timer', 'name': 'Telegram', 'function': None, 'kwargs': {}}
2017-10-06 03:10:21.051303 WARNING ------------------------------------------------------------
2017-10-06 03:10:21.059574 WARNING Traceback (most recent call last):
  File "/srv/homeassistant/lib/python3.4/site-packages/appdaemon/appdaemon.py", line 518, in worker
    function(ha.sanitize_timer_kwargs(args["kwargs"]))
TypeError: 'NoneType' object is not callable

2017-10-06 03:10:21.065109 WARNING ------------------------------------------------------------
2017-10-06 03:11:08.065052 WARNING ------------------------------------------------------------
2017-10-06 03:11:08.073356 WARNING Unexpected error in worker for App Telegram:
2017-10-06 03:11:08.084646 WARNING Worker Ags: {'id': UUID('c31c6ae0-fc11-49f4-9b75-9a452d09b0b2'), 'type': 'timer', 'name': 'Telegram', 'function': None, 'kwargs': {}}
2017-10-06 03:11:08.093256 WARNING ------------------------------------------------------------
2017-10-06 03:11:08.103321 WARNING Traceback (most recent call last):
  File "/srv/homeassistant/lib/python3.4/site-packages/appdaemon/appdaemon.py", line 518, in worker
    function(ha.sanitize_timer_kwargs(args["kwargs"]))
TypeError: 'NoneType' object is not callable

2017-10-06 03:11:08.115256 WARNING ------------------------------------------------------------
2017-10-06 03:11:20.031790 WARNING ------------------------------------------------------------
2017-10-06 03:11:20.037983 WARNING Unexpected error in worker for App Telegram:
2017-10-06 03:11:20.043433 WARNING Worker Ags: {'id': UUID('c31c6ae0-fc11-49f4-9b75-9a452d09b0b2'), 'type': 'timer', 'name': 'Telegram', 'function': None, 'kwargs': {}}
2017-10-06 03:11:20.047531 WARNING ------------------------------------------------------------
2017-10-06 03:11:20.054591 WARNING Traceback (most recent call last):
  File "/srv/homeassistant/lib/python3.4/site-packages/appdaemon/appdaemon.py", line 518, in worker
    function(ha.sanitize_timer_kwargs(args["kwargs"]))
TypeError: 'NoneType' object is not callable

2017-10-06 03:11:20.060017 WARNING ------------------------------------------------------------
2017-10-06 03:13:33.086688 WARNING ------------------------------------------------------------
2017-10-06 03:13:33.100416 WARNING Unexpected error in worker for App Telegram:
2017-10-06 03:13:33.114595 WARNING Worker Ags: {'id': UUID('c31c6ae0-fc11-49f4-9b75-9a452d09b0b2'), 'type': 'timer', 'name': 'Telegram', 'function': None, 'kwargs': {}}
2017-10-06 03:13:33.118991 WARNING ------------------------------------------------------------
2017-10-06 03:13:33.124013 WARNING Traceback (most recent call last):
  File "/srv/homeassistant/lib/python3.4/site-packages/appdaemon/appdaemon.py", line 518, in worker
    function(ha.sanitize_timer_kwargs(args["kwargs"]))
TypeError: 'NoneType' object is not callable

2017-10-06 03:13:33.128107 WARNING ------------------------------------------------------------
2017-10-06 03:26:11.290719 WARNING ------------------------------------------------------------
2017-10-06 03:26:11.337273 WARNING Unexpected error in worker for App Telegram:
2017-10-06 03:26:11.347888 WARNING Worker Ags: {'id': UUID('d0a7e3fd-8eb5-4513-b8c8-7ce95e83e34f'), 'data': {'from_first': 'Legendary', 'from_last': 'Dav', 'text': 'unbypass downstairs', 'user_id': 396287366, 'chat_id': 396287366}, 'name': 'Telegram', 'function': <bound method TelegramBotEventListener.receive_telegram_text of <telegram.TelegramBotEventListener object at 0xb5a9def0>>, 'type': 'event', 'event': 'telegram_text', 'kwargs': {}}
2017-10-06 03:26:11.372976 WARNING ------------------------------------------------------------
2017-10-06 03:26:11.413086 WARNING Traceback (most recent call last):
  File "/srv/homeassistant/lib/python3.4/site-packages/appdaemon/appdaemon.py", line 528, in worker
    function(args["event"], data, args["kwargs"])
  File "/home/homeassistant/config/appdaemon/apps/telegram.py", line 107, in receive_telegram_text
    self.bypassZone(payload_event, accessgroup)
  File "/home/homeassistant/config/appdaemon/apps/telegram.py", line 190, in bypassZone
    self.listenForService()
TypeError: listenForService() takes 0 positional arguments but 1 was given

2017-10-06 03:26:11.458548 WARNING ------------------------------------------------------------
2017-10-06 03:26:30.062069 WARNING ------------------------------------------------------------
2017-10-06 03:26:30.066630 WARNING Unexpected error during loading of telegram.py:
2017-10-06 03:26:30.070546 WARNING ------------------------------------------------------------
2017-10-06 03:26:30.077340 WARNING Traceback (most recent call last):
  File "/srv/homeassistant/lib/python3.4/site-packages/appdaemon/appdaemon.py", line 903, in read_app
    importlib.reload(conf.modules[module_name])
  File "/srv/homeassistant/lib/python3.4/importlib/__init__.py", line 149, in reload
    methods.exec(module)
  File "<frozen importlib._bootstrap>", line 1153, in exec
  File "<frozen importlib._bootstrap>", line 1129, in _exec
  File "<frozen importlib._bootstrap>", line 1467, in exec_module
  File "<frozen importlib._bootstrap>", line 1572, in get_code
  File "<frozen importlib._bootstrap>", line 1532, in source_to_code
  File "<frozen importlib._bootstrap>", line 321, in _call_with_frames_removed
  File "/home/homeassistant/config/appdaemon/apps/telegram.py", line 173
    def listenForService(self)
                             ^
SyntaxError: invalid syntax

2017-10-06 03:26:30.081489 WARNING ------------------------------------------------------------
2017-10-06 03:26:38.928612 WARNING ------------------------------------------------------------
2017-10-06 03:26:38.936287 WARNING Unexpected error in worker for App Telegram:
2017-10-06 03:26:38.948722 WARNING Worker Ags: {'id': UUID('acc15081-7c9f-43c0-962e-d575939610e1'), 'data': {'from_first': 'Legendary', 'from_last': 'Dav', 'text': 'unbypass downstairs', 'user_id': 396287366, 'chat_id': 396287366}, 'name': 'Telegram', 'function': <bound method TelegramBotEventListener.receive_telegram_text of <telegram.TelegramBotEventListener object at 0xb5b30f10>>, 'type': 'event', 'event': 'telegram_text', 'kwargs': {}}
2017-10-06 03:26:38.954116 WARNING ------------------------------------------------------------
2017-10-06 03:26:38.978672 WARNING Traceback (most recent call last):
  File "/srv/homeassistant/lib/python3.4/site-packages/appdaemon/appdaemon.py", line 528, in worker
    function(args["event"], data, args["kwargs"])
  File "/home/homeassistant/config/appdaemon/apps/telegram.py", line 107, in receive_telegram_text
    self.bypassZone(payload_event, accessgroup)
  File "/home/homeassistant/config/appdaemon/apps/telegram.py", line 190, in bypassZone
    self.listenForService()
  File "/home/homeassistant/config/appdaemon/apps/telegram.py", line 174, in listenForService
    self.listen_event(self.executeShit(),'call_service')
TypeError: executeShit() missing 2 required positional arguments: 'event_id' and 'payload_event'

2017-10-06 03:26:38.991301 WARNING ------------------------------------------------------------
2017-10-06 03:32:01.033158 WARNING ------------------------------------------------------------
2017-10-06 03:32:01.037899 WARNING Unexpected error in worker for App Telegram:
2017-10-06 03:32:01.044876 WARNING Worker Ags: {'id': UUID('01d777d6-e913-4f46-8a6a-d8e31907e351'), 'type': 'timer', 'name': 'Telegram', 'function': <bound method TelegramBotEventListener.executeShit of <telegram.TelegramBotEventListener object at 0xb5a530b0>>, 'kwargs': {}}
2017-10-06 03:32:01.049986 WARNING ------------------------------------------------------------
2017-10-06 03:32:01.065520 WARNING Traceback (most recent call last):
  File "/srv/homeassistant/lib/python3.4/site-packages/appdaemon/appdaemon.py", line 518, in worker
    function(ha.sanitize_timer_kwargs(args["kwargs"]))
  File "/home/homeassistant/config/appdaemon/apps/telegram.py", line 172, in executeShit
    self.log("event_id - {} = {}".format(kwags))
IndexError: tuple index out of range

2017-10-06 03:32:01.070409 WARNING ------------------------------------------------------------
2017-10-06 03:33:07.899156 WARNING ------------------------------------------------------------
2017-10-06 03:33:07.913143 WARNING Unexpected error in worker for App Telegram:
2017-10-06 03:33:07.919413 WARNING Worker Ags: {'id': UUID('ddaaa1d7-cdc7-40ea-b24f-da8ab889af7e'), 'data': {'from_first': 'Legendary', 'from_last': 'Dav', 'text': 'bypass downstairs', 'user_id': 396287366, 'chat_id': 396287366}, 'name': 'Telegram', 'function': <bound method TelegramBotEventListener.receive_telegram_text of <telegram.TelegramBotEventListener object at 0xb5af6330>>, 'type': 'event', 'event': 'telegram_text', 'kwargs': {}}
2017-10-06 03:33:07.927233 WARNING ------------------------------------------------------------
2017-10-06 03:33:07.953239 WARNING Traceback (most recent call last):
  File "/srv/homeassistant/lib/python3.4/site-packages/appdaemon/appdaemon.py", line 528, in worker
    function(args["event"], data, args["kwargs"])
  File "/home/homeassistant/config/appdaemon/apps/telegram.py", line 107, in receive_telegram_text
    self.bypassZone(payload_event, accessgroup)
  File "/home/homeassistant/config/appdaemon/apps/telegram.py", line 192, in bypassZone
    self.run_in(self.executeShit(handle = handle),5)
TypeError: executeShit() got an unexpected keyword argument 'handle'

2017-10-06 03:33:07.957982 WARNING ------------------------------------------------------------
2017-10-06 03:35:35.945210 WARNING ------------------------------------------------------------
2017-10-06 03:35:35.949804 WARNING Unexpected error in worker for App Telegram:
2017-10-06 03:35:35.954210 WARNING Worker Ags: {'id': UUID('949b615a-bc4e-48d5-b507-022bb1274742'), 'data': {'from_first': 'Legendary', 'from_last': 'Dav', 'text': 'bypass downstairs', 'user_id': 396287366, 'chat_id': 396287366}, 'name': 'Telegram', 'function': <bound method TelegramBotEventListener.receive_telegram_text of <telegram.TelegramBotEventListener object at 0xb5b30eb0>>, 'type': 'event', 'event': 'telegram_text', 'kwargs': {}}
2017-10-06 03:35:35.970638 WARNING ------------------------------------------------------------
2017-10-06 03:35:35.988753 WARNING Traceback (most recent call last):
  File "/srv/homeassistant/lib/python3.4/site-packages/appdaemon/appdaemon.py", line 528, in worker
    function(args["event"], data, args["kwargs"])
  File "/home/homeassistant/config/appdaemon/apps/telegram.py", line 107, in receive_telegram_text
    self.bypassZone(payload_event, accessgroup)
  File "/home/homeassistant/config/appdaemon/apps/telegram.py", line 192, in bypassZone
    self.run_in(self.bypass,5,self = self,payload_event = payload_event,accessgroup = accessgroup)
TypeError: run_in() got multiple values for argument 'self'

2017-10-06 03:35:35.995856 WARNING ------------------------------------------------------------
2017-10-06 03:35:56.032716 WARNING ------------------------------------------------------------
2017-10-06 03:35:56.037804 WARNING Unexpected error in worker for App Telegram:
2017-10-06 03:35:56.045776 WARNING Worker Ags: {'id': UUID('d6553b76-779a-43b8-a73e-7b78956ec195'), 'type': 'timer', 'name': 'Telegram', 'function': <bound method TelegramBotEventListener.bypass of <telegram.TelegramBotEventListener object at 0xb5ae3850>>, 'kwargs': {'accessgroup': {'chatids': ['444908880', '396287366'], 'scenes': ['script.new'], 'lights': ['switch.kitchen', 'switch.living_room', 'switch.dummy', 'switch.tarinis_bedroom', 'light.lamp', 'light.lounge', 'light.gateway_light_34ce0088d613'], 'groupname': 'admin', 'rooms': ['group.living_room', 'group.bathroom', 'group.bedroom', 'group.kitchen'], 'menu': ['Alarm Functions', 'Rooms', 'Lights,Switches,Scenes', 'Cameras'], 'alarm': {'functions': ['nonee']}, 'switches': ['switch.tv', 'switch.living_room_outlet_2', 'switch.kettle', 'switch.bedroom_outlet']}, 'payload_event': {'from_first': 'Legendary', 'from_last': 'Dav', 'text': 'bypass downstairs', 'user_id': 396287366, 'chat_id': 396287366}}}
2017-10-06 03:35:56.052507 WARNING ------------------------------------------------------------
2017-10-06 03:35:56.059221 WARNING Traceback (most recent call last):
  File "/srv/homeassistant/lib/python3.4/site-packages/appdaemon/appdaemon.py", line 518, in worker
    function(ha.sanitize_timer_kwargs(args["kwargs"]))
TypeError: bypass() missing 1 required positional argument: 'accessgroup'

2017-10-06 03:35:56.065752 WARNING ------------------------------------------------------------
2017-10-06 03:37:41.034135 WARNING ------------------------------------------------------------
2017-10-06 03:37:41.039170 WARNING Unexpected error in worker for App Telegram:
2017-10-06 03:37:41.045424 WARNING Worker Ags: {'id': UUID('aa3ca2ed-45cb-4b5d-af21-4a2bd564bb76'), 'type': 'timer', 'name': 'Telegram', 'function': <bound method TelegramBotEventListener.bypass of <telegram.TelegramBotEventListener object at 0xb5af3070>>, 'kwargs': {'payload_event': {'from_first': 'Legendary', 'from_last': 'Dav', 'text': 'unbypass downstairs', 'user_id': 396287366, 'chat_id': 396287366}}}
2017-10-06 03:37:41.049488 WARNING ------------------------------------------------------------
2017-10-06 03:37:41.058200 WARNING Traceback (most recent call last):
  File "/srv/homeassistant/lib/python3.4/site-packages/appdaemon/appdaemon.py", line 518, in worker
    function(ha.sanitize_timer_kwargs(args["kwargs"]))
TypeError: bypass() missing 1 required positional argument: 'accessgroup'

2017-10-06 03:37:41.064602 WARNING ------------------------------------------------------------
2017-10-06 03:38:25.033392 WARNING ------------------------------------------------------------
2017-10-06 03:38:25.038220 WARNING Unexpected error in worker for App Telegram:
2017-10-06 03:38:25.047360 WARNING Worker Ags: {'id': UUID('f15f6a43-95cc-4ccf-ad1c-fe4ca6bb3df3'), 'type': 'timer', 'name': 'Telegram', 'function': None, 'kwargs': {'payload_event': {'from_first': 'Legendary', 'from_last': 'Dav', 'text': 'unbypass downstairs', 'user_id': 396287366, 'chat_id': 396287366}}}
2017-10-06 03:38:25.053501 WARNING ------------------------------------------------------------
2017-10-06 03:38:25.059785 WARNING Traceback (most recent call last):
  File "/srv/homeassistant/lib/python3.4/site-packages/appdaemon/appdaemon.py", line 518, in worker
    function(ha.sanitize_timer_kwargs(args["kwargs"]))
TypeError: 'NoneType' object is not callable

2017-10-06 03:38:25.069373 WARNING ------------------------------------------------------------
2017-10-06 03:39:55.065260 WARNING ------------------------------------------------------------
2017-10-06 03:39:55.070032 WARNING Unexpected error during loading of telegram.py:
2017-10-06 03:39:55.073898 WARNING ------------------------------------------------------------
2017-10-06 03:39:55.080975 WARNING Traceback (most recent call last):
  File "/srv/homeassistant/lib/python3.4/site-packages/appdaemon/appdaemon.py", line 903, in read_app
    importlib.reload(conf.modules[module_name])
  File "/srv/homeassistant/lib/python3.4/importlib/__init__.py", line 149, in reload
    methods.exec(module)
  File "<frozen importlib._bootstrap>", line 1153, in exec
  File "<frozen importlib._bootstrap>", line 1129, in _exec
  File "<frozen importlib._bootstrap>", line 1467, in exec_module
  File "<frozen importlib._bootstrap>", line 1572, in get_code
  File "<frozen importlib._bootstrap>", line 1532, in source_to_code
  File "<frozen importlib._bootstrap>", line 321, in _call_with_frames_removed
  File "/home/homeassistant/config/appdaemon/apps/telegram.py", line 196
    self.log("kwargs = {}".format(kwargs))
                                         ^
TabError: inconsistent use of tabs and spaces in indentation

2017-10-06 03:39:55.085370 WARNING ------------------------------------------------------------
2017-10-06 03:39:56.081391 WARNING ------------------------------------------------------------
2017-10-06 03:39:56.086033 WARNING Unexpected error during loading of telegram.py:
2017-10-06 03:39:56.092473 WARNING ------------------------------------------------------------
2017-10-06 03:39:56.100778 WARNING Traceback (most recent call last):
  File "/srv/homeassistant/lib/python3.4/site-packages/appdaemon/appdaemon.py", line 903, in read_app
    importlib.reload(conf.modules[module_name])
  File "/srv/homeassistant/lib/python3.4/importlib/__init__.py", line 149, in reload
    methods.exec(module)
  File "<frozen importlib._bootstrap>", line 1153, in exec
  File "<frozen importlib._bootstrap>", line 1129, in _exec
  File "<frozen importlib._bootstrap>", line 1467, in exec_module
  File "<frozen importlib._bootstrap>", line 1572, in get_code
  File "<frozen importlib._bootstrap>", line 1532, in source_to_code
  File "<frozen importlib._bootstrap>", line 321, in _call_with_frames_removed
  File "/home/homeassistant/config/appdaemon/apps/telegram.py", line 196
    self.log("kwargs = {}".format(kwargs))
                                         ^
TabError: inconsistent use of tabs and spaces in indentation

2017-10-06 03:39:56.105131 WARNING ------------------------------------------------------------
2017-10-06 03:40:17.033137 WARNING ------------------------------------------------------------
2017-10-06 03:40:17.037895 WARNING Unexpected error in worker for App Telegram:
2017-10-06 03:40:17.044780 WARNING Worker Ags: {'id': UUID('11431025-eb66-44c2-bf5e-05013cf2c8cc'), 'type': 'timer', 'name': 'Telegram', 'function': <bound method TelegramBotEventListener.bypass of <telegram.TelegramBotEventListener object at 0xb5b04250>>, 'kwargs': {'accessgroup': {'chatids': ['444908880', '396287366'], 'scenes': ['script.new'], 'lights': ['switch.kitchen', 'switch.living_room', 'switch.dummy', 'switch.tarinis_bedroom', 'light.lamp', 'light.lounge', 'light.gateway_light_34ce0088d613'], 'groupname': 'admin', 'rooms': ['group.living_room', 'group.bathroom', 'group.bedroom', 'group.kitchen'], 'menu': ['Alarm Functions', 'Rooms', 'Lights,Switches,Scenes', 'Cameras'], 'alarm': {'functions': ['nonee']}, 'switches': ['switch.tv', 'switch.living_room_outlet_2', 'switch.kettle', 'switch.bedroom_outlet']}, 'payload_event': {'from_first': 'Legendary', 'from_last': 'Dav', 'text': 'bypass downstairs', 'user_id': 396287366, 'chat_id': 396287366}}}
2017-10-06 03:40:17.051526 WARNING ------------------------------------------------------------
2017-10-06 03:40:17.065526 WARNING Traceback (most recent call last):
  File "/srv/homeassistant/lib/python3.4/site-packages/appdaemon/appdaemon.py", line 518, in worker
    function(ha.sanitize_timer_kwargs(args["kwargs"]))
  File "/home/homeassistant/config/appdaemon/apps/telegram.py", line 196, in bypass
    self.log("kwargs = {}".format(kwargs))
NameError: name 'self' is not defined

2017-10-06 03:40:17.070230 WARNING ------------------------------------------------------------
2017-10-06 03:41:16.098781 WARNING ------------------------------------------------------------
2017-10-06 03:41:16.106915 WARNING Unexpected error in worker for App Telegram:
2017-10-06 03:41:16.116155 WARNING Worker Ags: {'id': UUID('4dd7e316-ec8d-4ff1-b8c6-0b07ac5264ac'), 'type': 'timer', 'name': 'Telegram', 'function': <bound method TelegramBotEventListener.bypass of <telegram.TelegramBotEventListener object at 0xb5a532b0>>, 'kwargs': {'accessgroup': {'chatids': ['444908880', '396287366'], 'scenes': ['script.new'], 'lights': ['switch.kitchen', 'switch.living_room', 'switch.dummy', 'switch.tarinis_bedroom', 'light.lamp', 'light.lounge', 'light.gateway_light_34ce0088d613'], 'groupname': 'admin', 'rooms': ['group.living_room', 'group.bathroom', 'group.bedroom', 'group.kitchen'], 'menu': ['Alarm Functions', 'Rooms', 'Lights,Switches,Scenes', 'Cameras'], 'alarm': {'functions': ['nonee']}, 'switches': ['switch.tv', 'switch.living_room_outlet_2', 'switch.kettle', 'switch.bedroom_outlet']}, 'payload_event': {'from_first': 'Legendary', 'from_last': 'Dav', 'text': 'bypass downstairs', 'user_id': 396287366, 'chat_id': 396287366}}}
2017-10-06 03:41:16.135895 WARNING ------------------------------------------------------------
2017-10-06 03:41:16.149208 WARNING Traceback (most recent call last):
  File "/srv/homeassistant/lib/python3.4/site-packages/appdaemon/appdaemon.py", line 518, in worker
    function(ha.sanitize_timer_kwargs(args["kwargs"]))
  File "/home/homeassistant/config/appdaemon/apps/telegram.py", line 217, in bypass
    target = payload_event['chat_id'],
NameError: name 'payload_event' is not defined

2017-10-06 03:41:16.165904 WARNING ------------------------------------------------------------
2017-10-06 03:48:18.053694 WARNING ------------------------------------------------------------
2017-10-06 03:48:18.057705 WARNING Unexpected error during loading of telegram.py:
2017-10-06 03:48:18.061505 WARNING ------------------------------------------------------------
2017-10-06 03:48:18.068707 WARNING Traceback (most recent call last):
  File "/srv/homeassistant/lib/python3.4/site-packages/appdaemon/appdaemon.py", line 903, in read_app
    importlib.reload(conf.modules[module_name])
  File "/srv/homeassistant/lib/python3.4/importlib/__init__.py", line 149, in reload
    methods.exec(module)
  File "<frozen importlib._bootstrap>", line 1153, in exec
  File "<frozen importlib._bootstrap>", line 1129, in _exec
  File "<frozen importlib._bootstrap>", line 1467, in exec_module
  File "<frozen importlib._bootstrap>", line 1572, in get_code
  File "<frozen importlib._bootstrap>", line 1532, in source_to_code
  File "<frozen importlib._bootstrap>", line 321, in _call_with_frames_removed
  File "/home/homeassistant/config/appdaemon/apps/telegram.py", line 97
    simpleFunction(self,payload event = payload_event,payloadevent = accessgroup)
                                    ^
SyntaxError: invalid syntax

2017-10-06 03:48:18.072699 WARNING ------------------------------------------------------------
2017-10-06 03:52:39.114916 WARNING ------------------------------------------------------------
2017-10-06 03:52:39.124760 WARNING Unexpected error in worker for App Telegram:
2017-10-06 03:52:39.128845 WARNING Worker Ags: {'id': UUID('9071ef76-b9e2-45c9-b895-eb14fbde5490'), 'data': {'from_first': 'Legendary', 'from_last': 'Dav', 'text': 'Zone Bypass', 'user_id': 396287366, 'chat_id': 396287366}, 'name': 'Telegram', 'function': <bound method TelegramBotEventListener.receive_telegram_text of <telegram.TelegramBotEventListener object at 0xb5b4d6b0>>, 'type': 'event', 'event': 'telegram_text', 'kwargs': {}}
2017-10-06 03:52:39.132824 WARNING ------------------------------------------------------------
2017-10-06 03:52:39.152576 WARNING Traceback (most recent call last):
  File "/srv/homeassistant/lib/python3.4/site-packages/appdaemon/appdaemon.py", line 528, in worker
    function(args["event"], data, args["kwargs"])
  File "/home/homeassistant/config/appdaemon/apps/telegram.py", line 97, in receive_telegram_text
    simpleFunction(self, payload_event = payload_event,accessgroup = accessgroup)
TypeError: bypass() got an unexpected keyword argument 'payload_event'

2017-10-06 03:52:39.160738 WARNING ------------------------------------------------------------
2017-10-06 03:53:57.540305 WARNING ------------------------------------------------------------
2017-10-06 03:53:57.554763 WARNING Unexpected error in worker for App Telegram:
2017-10-06 03:53:57.558882 WARNING Worker Ags: {'id': UUID('8465237a-9933-4333-8265-ee632d15f0f8'), 'data': {'from_first': 'Legendary', 'from_last': 'Dav', 'text': 'Zone Bypass', 'user_id': 396287366, 'chat_id': 396287366}, 'name': 'Telegram', 'function': <bound method TelegramBotEventListener.receive_telegram_text of <telegram.TelegramBotEventListener object at 0xb5b30cb0>>, 'type': 'event', 'event': 'telegram_text', 'kwargs': {}}
2017-10-06 03:53:57.562843 WARNING ------------------------------------------------------------
2017-10-06 03:53:57.581483 WARNING Traceback (most recent call last):
  File "/srv/homeassistant/lib/python3.4/site-packages/appdaemon/appdaemon.py", line 528, in worker
    function(args["event"], data, args["kwargs"])
  File "/home/homeassistant/config/appdaemon/apps/telegram.py", line 97, in receive_telegram_text
    simpleFunction(self, payload_event = payload_event,accessgroup = accessgroup)
  File "/home/homeassistant/config/appdaemon/apps/telegram.py", line 196, in bypass
    self.log("kwargs = {}".format(kwargs))
NameError: name 'kwargs' is not defined

2017-10-06 03:53:57.594738 WARNING ------------------------------------------------------------
2017-10-06 03:57:23.032363 WARNING ------------------------------------------------------------
2017-10-06 03:57:23.036367 WARNING Unexpected error in worker for App Telegram:
2017-10-06 03:57:23.041175 WARNING Worker Ags: {'id': UUID('129b6b83-edb0-401b-bb77-8e60302dc716'), 'type': 'timer', 'name': 'Telegram', 'function': <bound method TelegramBotEventListener.executeShit of <telegram.TelegramBotEventListener object at 0xb5b30850>>, 'kwargs': {'accessgroup': {'chatids': ['444908880', '396287366'], 'scenes': ['script.new'], 'lights': ['switch.kitchen', 'switch.living_room', 'switch.dummy', 'switch.tarinis_bedroom', 'light.lamp', 'light.lounge', 'light.gateway_light_34ce0088d613'], 'groupname': 'admin', 'rooms': ['group.living_room', 'group.bathroom', 'group.bedroom', 'group.kitchen'], 'menu': ['Alarm Functions', 'Rooms', 'Lights,Switches,Scenes', 'Cameras'], 'alarm': {'functions': ['nonee']}, 'switches': ['switch.tv', 'switch.living_room_outlet_2', 'switch.kettle', 'switch.bedroom_outlet']}, 'payload_event': {'from_first': 'Legendary', 'from_last': 'Dav', 'text': 'unbypass downstairs', 'user_id': 396287366, 'chat_id': 396287366}}}
2017-10-06 03:57:23.045497 WARNING ------------------------------------------------------------
2017-10-06 03:57:23.050181 WARNING Traceback (most recent call last):
  File "/srv/homeassistant/lib/python3.4/site-packages/appdaemon/appdaemon.py", line 518, in worker
    function(ha.sanitize_timer_kwargs(args["kwargs"]))
TypeError: executeShit() missing 1 required positional argument: 'accessgroup'

2017-10-06 03:57:23.053896 WARNING ------------------------------------------------------------
2017-10-06 03:59:08.033163 WARNING ------------------------------------------------------------
2017-10-06 03:59:08.037226 WARNING Unexpected error in worker for App Telegram:
2017-10-06 03:59:08.041475 WARNING Worker Ags: {'id': UUID('8b4e9309-2dc5-4d81-a8f1-6127cd5f4661'), 'type': 'timer', 'name': 'Telegram', 'function': <bound method TelegramBotEventListener.executeShit of <telegram.TelegramBotEventListener object at 0xb5938a30>>, 'kwargs': {'accessgroup': {'chatids': ['444908880', '396287366'], 'scenes': ['script.new'], 'lights': ['switch.kitchen', 'switch.living_room', 'switch.dummy', 'switch.tarinis_bedroom', 'light.lamp', 'light.lounge', 'light.gateway_light_34ce0088d613'], 'groupname': 'admin', 'rooms': ['group.living_room', 'group.bathroom', 'group.bedroom', 'group.kitchen'], 'menu': ['Alarm Functions', 'Rooms', 'Lights,Switches,Scenes', 'Cameras'], 'alarm': {'functions': ['nonee']}, 'switches': ['switch.tv', 'switch.living_room_outlet_2', 'switch.kettle', 'switch.bedroom_outlet']}, 'payload_event': {'from_first': 'Legendary', 'from_last': 'Dav', 'text': 'unbypass downstairs', 'user_id': 396287366, 'chat_id': 396287366}}}
2017-10-06 03:59:08.045855 WARNING ------------------------------------------------------------
2017-10-06 03:59:08.050539 WARNING Traceback (most recent call last):
  File "/srv/homeassistant/lib/python3.4/site-packages/appdaemon/appdaemon.py", line 518, in worker
    function(ha.sanitize_timer_kwargs(args["kwargs"]))
TypeError: executeShit() missing 1 required positional argument: 'accessgroup'

2017-10-06 03:59:08.054642 WARNING ------------------------------------------------------------
2017-10-06 04:00:18.032667 WARNING ------------------------------------------------------------
2017-10-06 04:00:18.036730 WARNING Unexpected error in worker for App Telegram:
2017-10-06 04:00:18.041305 WARNING Worker Ags: {'id': UUID('c4988310-7b3e-46c9-a856-f41e002bbfe6'), 'type': 'timer', 'name': 'Telegram', 'function': <bound method TelegramBotEventListener.bypass of <telegram.TelegramBotEventListener object at 0xb5afd830>>, 'kwargs': {'accessgroup': {'chatids': ['444908880', '396287366'], 'scenes': ['script.new'], 'lights': ['switch.kitchen', 'switch.living_room', 'switch.dummy', 'switch.tarinis_bedroom', 'light.lamp', 'light.lounge', 'light.gateway_light_34ce0088d613'], 'groupname': 'admin', 'rooms': ['group.living_room', 'group.bathroom', 'group.bedroom', 'group.kitchen'], 'menu': ['Alarm Functions', 'Rooms', 'Lights,Switches,Scenes', 'Cameras'], 'alarm': {'functions': ['nonee']}, 'switches': ['switch.tv', 'switch.living_room_outlet_2', 'switch.kettle', 'switch.bedroom_outlet']}, 'payload_event': {'from_first': 'Legendary', 'from_last': 'Dav', 'text': 'unbypass downstairs', 'user_id': 396287366, 'chat_id': 396287366}}}
2017-10-06 04:00:18.045343 WARNING ------------------------------------------------------------
2017-10-06 04:00:18.050336 WARNING Traceback (most recent call last):
  File "/srv/homeassistant/lib/python3.4/site-packages/appdaemon/appdaemon.py", line 518, in worker
    function(ha.sanitize_timer_kwargs(args["kwargs"]))
TypeError: bypass() missing 1 required positional argument: 'accessgroup'

2017-10-06 04:00:18.054075 WARNING ------------------------------------------------------------
2017-10-06 04:02:46.587341 WARNING ------------------------------------------------------------
2017-10-06 04:02:46.604757 WARNING Unexpected error in worker for App Telegram:
2017-10-06 04:02:46.608753 WARNING Worker Ags: {'id': UUID('9c7ef33b-5136-4b5d-8414-699b1ba288c0'), 'data': {'from_first': 'Legendary', 'from_last': 'Dav', 'text': 'Zone Bypass', 'user_id': 396287366, 'chat_id': 396287366}, 'name': 'Telegram', 'function': <bound method TelegramBotEventListener.receive_telegram_text of <telegram.TelegramBotEventListener object at 0xb5a536f0>>, 'type': 'event', 'event': 'telegram_text', 'kwargs': {}}
2017-10-06 04:02:46.615826 WARNING ------------------------------------------------------------
2017-10-06 04:02:46.630805 WARNING Traceback (most recent call last):
  File "/srv/homeassistant/lib/python3.4/site-packages/appdaemon/appdaemon.py", line 528, in worker
    function(args["event"], data, args["kwargs"])
  File "/home/homeassistant/config/appdaemon/apps/telegram.py", line 97, in receive_telegram_text
    simpleFunction(self, payload_event = payload_event,accessgroup = accessgroup)
TypeError: bypass() got an unexpected keyword argument 'payload_event'

2017-10-06 04:02:46.644738 WARNING ------------------------------------------------------------
2017-10-06 04:04:38.049848 WARNING ------------------------------------------------------------
2017-10-06 04:04:38.054360 WARNING Unexpected error during loading of telegram.py:
2017-10-06 04:04:38.058420 WARNING ------------------------------------------------------------
2017-10-06 04:04:38.066436 WARNING Traceback (most recent call last):
  File "/srv/homeassistant/lib/python3.4/site-packages/appdaemon/appdaemon.py", line 903, in read_app
    importlib.reload(conf.modules[module_name])
  File "/srv/homeassistant/lib/python3.4/importlib/__init__.py", line 149, in reload
    methods.exec(module)
  File "<frozen importlib._bootstrap>", line 1153, in exec
  File "<frozen importlib._bootstrap>", line 1129, in _exec
  File "<frozen importlib._bootstrap>", line 1467, in exec_module
  File "<frozen importlib._bootstrap>", line 1572, in get_code
  File "<frozen importlib._bootstrap>", line 1532, in source_to_code
  File "<frozen importlib._bootstrap>", line 321, in _call_with_frames_removed
  File "/home/homeassistant/config/appdaemon/apps/telegram.py", line 97
    simpleFunction(self, args = {payload_event = payload_event, accessgroup = accessgroup})
                                               ^
SyntaxError: invalid syntax

2017-10-06 04:04:38.070331 WARNING ------------------------------------------------------------
2017-10-06 04:04:39.049100 WARNING ------------------------------------------------------------
2017-10-06 04:04:39.054762 WARNING Unexpected error during loading of telegram.py:
2017-10-06 04:04:39.058768 WARNING ------------------------------------------------------------
2017-10-06 04:04:39.067025 WARNING Traceback (most recent call last):
  File "/srv/homeassistant/lib/python3.4/site-packages/appdaemon/appdaemon.py", line 903, in read_app
    importlib.reload(conf.modules[module_name])
  File "/srv/homeassistant/lib/python3.4/importlib/__init__.py", line 149, in reload
    methods.exec(module)
  File "<frozen importlib._bootstrap>", line 1153, in exec
  File "<frozen importlib._bootstrap>", line 1129, in _exec
  File "<frozen importlib._bootstrap>", line 1467, in exec_module
  File "<frozen importlib._bootstrap>", line 1572, in get_code
  File "<frozen importlib._bootstrap>", line 1532, in source_to_code
  File "<frozen importlib._bootstrap>", line 321, in _call_with_frames_removed
  File "/home/homeassistant/config/appdaemon/apps/telegram.py", line 97
    simpleFunction(self, args = {payload_event = payload_event, accessgroup = accessgroup})
                                               ^
SyntaxError: invalid syntax

2017-10-06 04:04:39.070968 WARNING ------------------------------------------------------------
2017-10-06 04:05:08.411958 WARNING ------------------------------------------------------------
2017-10-06 04:05:08.424758 WARNING Unexpected error in worker for App Telegram:
2017-10-06 04:05:08.428970 WARNING Worker Ags: {'id': UUID('a547996a-9c24-4788-8748-3c6dc5d24a62'), 'data': {'from_first': 'Legendary', 'from_last': 'Dav', 'text': '🏠 Menu', 'user_id': 396287366, 'chat_id': 396287366}, 'name': 'Telegram', 'function': <bound method TelegramBotEventListener.receive_telegram_text of <telegram.TelegramBotEventListener object at 0xb5af3790>>, 'type': 'event', 'event': 'telegram_text', 'kwargs': {}}
2017-10-06 04:05:08.440823 WARNING ------------------------------------------------------------
2017-10-06 04:05:08.451340 WARNING Traceback (most recent call last):
  File "/srv/homeassistant/lib/python3.4/site-packages/appdaemon/appdaemon.py", line 528, in worker
    function(args["event"], data, args["kwargs"])
  File "/home/homeassistant/config/appdaemon/apps/telegram.py", line 97, in receive_telegram_text
    simpleFunction(self, args = {'payload_event': payload_event, 'accessgroup': accessgroup})
TypeError: printMenu() got an unexpected keyword argument 'args'

2017-10-06 04:05:08.464742 WARNING ------------------------------------------------------------
2017-10-06 04:05:43.729518 WARNING ------------------------------------------------------------
2017-10-06 04:05:43.733116 WARNING Unexpected error in worker for App Telegram:
2017-10-06 04:05:43.745340 WARNING Worker Ags: {'id': UUID('a547996a-9c24-4788-8748-3c6dc5d24a62'), 'data': {'from_first': 'Legendary', 'from_last': 'Dav', 'text': 'Zone Bypass', 'user_id': 396287366, 'chat_id': 396287366}, 'name': 'Telegram', 'function': <bound method TelegramBotEventListener.receive_telegram_text of <telegram.TelegramBotEventListener object at 0xb5af3790>>, 'type': 'event', 'event': 'telegram_text', 'kwargs': {}}
2017-10-06 04:05:43.749137 WARNING ------------------------------------------------------------
2017-10-06 04:05:43.760298 WARNING Traceback (most recent call last):
  File "/srv/homeassistant/lib/python3.4/site-packages/appdaemon/appdaemon.py", line 528, in worker
    function(args["event"], data, args["kwargs"])
  File "/home/homeassistant/config/appdaemon/apps/telegram.py", line 97, in receive_telegram_text
    simpleFunction(self, args = {'payload_event': payload_event, 'accessgroup': accessgroup})
TypeError: bypass() got an unexpected keyword argument 'args'

2017-10-06 04:05:43.764152 WARNING ------------------------------------------------------------
2017-10-06 04:08:09.295333 WARNING ------------------------------------------------------------
2017-10-06 04:08:09.302567 WARNING Unexpected error in worker for App Telegram:
2017-10-06 04:08:09.313504 WARNING Worker Ags: {'id': UUID('0ac64247-4a4b-4429-a3ef-f26fdbbed3a9'), 'data': {'from_first': 'Legendary', 'from_last': 'Dav', 'text': 'Alarm Functions', 'user_id': 396287366, 'chat_id': 396287366}, 'name': 'Telegram', 'function': <bound method TelegramBotEventListener.receive_telegram_text of <telegram.TelegramBotEventListener object at 0xb5b30e90>>, 'type': 'event', 'event': 'telegram_text', 'kwargs': {}}
2017-10-06 04:08:09.324943 WARNING ------------------------------------------------------------
2017-10-06 04:08:09.347677 WARNING Traceback (most recent call last):
  File "/srv/homeassistant/lib/python3.4/site-packages/appdaemon/appdaemon.py", line 528, in worker
    function(args["event"], data, args["kwargs"])
  File "/home/homeassistant/config/appdaemon/apps/telegram.py", line 97, in receive_telegram_text
    simpleFunction(self, tuple(payload_event = payload_event,accessgroup = accessgroup))
TypeError: tuple() takes at most 1 argument (2 given)

2017-10-06 04:08:09.354800 WARNING ------------------------------------------------------------
2017-10-06 04:08:20.895263 WARNING ------------------------------------------------------------
2017-10-06 04:08:20.904754 WARNING Unexpected error in worker for App Telegram:
2017-10-06 04:08:20.915008 WARNING Worker Ags: {'id': UUID('0ac64247-4a4b-4429-a3ef-f26fdbbed3a9'), 'data': {'from_first': 'Legendary', 'from_last': 'Dav', 'text': 'Zone Bypass', 'user_id': 396287366, 'chat_id': 396287366}, 'name': 'Telegram', 'function': <bound method TelegramBotEventListener.receive_telegram_text of <telegram.TelegramBotEventListener object at 0xb5b30e90>>, 'type': 'event', 'event': 'telegram_text', 'kwargs': {}}
2017-10-06 04:08:20.918691 WARNING ------------------------------------------------------------
2017-10-06 04:08:20.939682 WARNING Traceback (most recent call last):
  File "/srv/homeassistant/lib/python3.4/site-packages/appdaemon/appdaemon.py", line 528, in worker
    function(args["event"], data, args["kwargs"])
  File "/home/homeassistant/config/appdaemon/apps/telegram.py", line 97, in receive_telegram_text
    simpleFunction(self, tuple(payload_event = payload_event,accessgroup = accessgroup))
TypeError: tuple() takes at most 1 argument (2 given)

2017-10-06 04:08:20.943372 WARNING ------------------------------------------------------------
2017-10-06 04:08:53.052493 WARNING ------------------------------------------------------------
2017-10-06 04:08:53.061954 WARNING Unexpected error during loading of telegram.py:
2017-10-06 04:08:53.065726 WARNING ------------------------------------------------------------
2017-10-06 04:08:53.072745 WARNING Traceback (most recent call last):
  File "/srv/homeassistant/lib/python3.4/site-packages/appdaemon/appdaemon.py", line 903, in read_app
    importlib.reload(conf.modules[module_name])
  File "/srv/homeassistant/lib/python3.4/importlib/__init__.py", line 149, in reload
    methods.exec(module)
  File "<frozen importlib._bootstrap>", line 1153, in exec
  File "<frozen importlib._bootstrap>", line 1129, in _exec
  File "<frozen importlib._bootstrap>", line 1467, in exec_module
  File "<frozen importlib._bootstrap>", line 1572, in get_code
  File "<frozen importlib._bootstrap>", line 1532, in source_to_code
  File "<frozen importlib._bootstrap>", line 321, in _call_with_frames_removed
  File "/home/homeassistant/config/appdaemon/apps/telegram.py", line 97
    simpleFunction(self, tuple({payload_event = payload_event,accessgroup = accessgroup}))
                                              ^
SyntaxError: invalid syntax

2017-10-06 04:08:53.076888 WARNING ------------------------------------------------------------
2017-10-06 04:08:54.048683 WARNING ------------------------------------------------------------
2017-10-06 04:08:54.054081 WARNING Unexpected error during loading of telegram.py:
2017-10-06 04:08:54.059138 WARNING ------------------------------------------------------------
2017-10-06 04:08:54.066265 WARNING Traceback (most recent call last):
  File "/srv/homeassistant/lib/python3.4/site-packages/appdaemon/appdaemon.py", line 903, in read_app
    importlib.reload(conf.modules[module_name])
  File "/srv/homeassistant/lib/python3.4/importlib/__init__.py", line 149, in reload
    methods.exec(module)
  File "<frozen importlib._bootstrap>", line 1153, in exec
  File "<frozen importlib._bootstrap>", line 1129, in _exec
  File "<frozen importlib._bootstrap>", line 1467, in exec_module
  File "<frozen importlib._bootstrap>", line 1572, in get_code
  File "<frozen importlib._bootstrap>", line 1532, in source_to_code
  File "<frozen importlib._bootstrap>", line 321, in _call_with_frames_removed
  File "/home/homeassistant/config/appdaemon/apps/telegram.py", line 97
    simpleFunction(self, tuple({payload_event = payload_event,accessgroup = accessgroup}))
                                              ^
SyntaxError: invalid syntax

2017-10-06 04:08:54.070222 WARNING ------------------------------------------------------------
2017-10-06 04:09:33.838560 WARNING ------------------------------------------------------------
2017-10-06 04:09:33.854984 WARNING Unexpected error in worker for App Telegram:
2017-10-06 04:09:33.859164 WARNING Worker Ags: {'id': UUID('697f482d-57f4-4f21-94f2-12f90418e075'), 'data': {'from_first': 'Legendary', 'from_last': 'Dav', 'text': 'Zone Bypass', 'user_id': 396287366, 'chat_id': 396287366}, 'name': 'Telegram', 'function': <bound method TelegramBotEventListener.receive_telegram_text of <telegram.TelegramBotEventListener object at 0xb5788f50>>, 'type': 'event', 'event': 'telegram_text', 'kwargs': {}}
2017-10-06 04:09:33.863275 WARNING ------------------------------------------------------------
2017-10-06 04:09:33.873681 WARNING Traceback (most recent call last):
  File "/srv/homeassistant/lib/python3.4/site-packages/appdaemon/appdaemon.py", line 528, in worker
    function(args["event"], data, args["kwargs"])
  File "/home/homeassistant/config/appdaemon/apps/telegram.py", line 97, in receive_telegram_text
    simpleFunction(self, tuple(5))
TypeError: 'int' object is not iterable

2017-10-06 04:09:33.894820 WARNING ------------------------------------------------------------
2017-10-06 04:10:24.394829 WARNING ------------------------------------------------------------
2017-10-06 04:10:24.403438 WARNING Unexpected error in worker for App Telegram:
2017-10-06 04:10:24.415328 WARNING Worker Ags: {'id': UUID('885f5a11-f305-4d36-bf6a-38dde65678f5'), 'data': {'from_first': 'Legendary', 'from_last': 'Dav', 'text': 'Zone Bypass', 'user_id': 396287366, 'chat_id': 396287366}, 'name': 'Telegram', 'function': <bound method TelegramBotEventListener.receive_telegram_text of <telegram.TelegramBotEventListener object at 0xb5af6810>>, 'type': 'event', 'event': 'telegram_text', 'kwargs': {}}
2017-10-06 04:10:24.418997 WARNING ------------------------------------------------------------
2017-10-06 04:10:24.441272 WARNING Traceback (most recent call last):
  File "/srv/homeassistant/lib/python3.4/site-packages/appdaemon/appdaemon.py", line 528, in worker
    function(args["event"], data, args["kwargs"])
  File "/home/homeassistant/config/appdaemon/apps/telegram.py", line 97, in receive_telegram_text
    simpleFunction(self, tuple([3,4,5,3]))
  File "/home/homeassistant/config/appdaemon/apps/telegram.py", line 197, in bypass
    payload_event = args[0]['payload_event']
TypeError: tuple indices must be integers, not str

2017-10-06 04:10:24.445627 WARNING ------------------------------------------------------------
2017-10-06 04:11:20.165089 WARNING ------------------------------------------------------------
2017-10-06 04:11:20.171851 WARNING Unexpected error in worker for App Telegram:
2017-10-06 04:11:20.185225 WARNING Worker Ags: {'id': UUID('30d14ed3-9177-4c07-829b-9c2673b294cc'), 'data': {'from_first': 'Legendary', 'from_last': 'Dav', 'text': 'Zone Bypass', 'user_id': 396287366, 'chat_id': 396287366}, 'name': 'Telegram', 'function': <bound method TelegramBotEventListener.receive_telegram_text of <telegram.TelegramBotEventListener object at 0xb5938a30>>, 'type': 'event', 'event': 'telegram_text', 'kwargs': {}}
2017-10-06 04:11:20.188891 WARNING ------------------------------------------------------------
2017-10-06 04:11:20.212160 WARNING Traceback (most recent call last):
  File "/srv/homeassistant/lib/python3.4/site-packages/appdaemon/appdaemon.py", line 528, in worker
    function(args["event"], data, args["kwargs"])
  File "/home/homeassistant/config/appdaemon/apps/telegram.py", line 97, in receive_telegram_text
    simpleFunction(self, tuple([{'payload_event':payload_event,'accessgroup':accessgroup}]))
  File "/home/homeassistant/config/appdaemon/apps/telegram.py", line 197, in bypass
    payload_event = args[0]['payload_event']
TypeError: tuple indices must be integers, not str

2017-10-06 04:11:20.216192 WARNING ------------------------------------------------------------
2017-10-06 04:11:40.923521 WARNING ------------------------------------------------------------
2017-10-06 04:11:40.935689 WARNING Unexpected error in worker for App Telegram:
2017-10-06 04:11:40.939766 WARNING Worker Ags: {'id': UUID('4d6b1904-234e-41d9-bf73-98b31c3766bb'), 'data': {'from_first': 'Legendary', 'from_last': 'Dav', 'text': 'Zone Bypass', 'user_id': 396287366, 'chat_id': 396287366}, 'name': 'Telegram', 'function': <bound method TelegramBotEventListener.receive_telegram_text of <telegram.TelegramBotEventListener object at 0xb5afd110>>, 'type': 'event', 'event': 'telegram_text', 'kwargs': {}}
2017-10-06 04:11:40.949499 WARNING ------------------------------------------------------------
2017-10-06 04:11:40.962040 WARNING Traceback (most recent call last):
  File "/srv/homeassistant/lib/python3.4/site-packages/appdaemon/appdaemon.py", line 528, in worker
    function(args["event"], data, args["kwargs"])
  File "/home/homeassistant/config/appdaemon/apps/telegram.py", line 97, in receive_telegram_text
    simpleFunction(self, tuple([{'payload_event':payload_event,'accessgroup':accessgroup}]))
  File "/home/homeassistant/config/appdaemon/apps/telegram.py", line 197, in bypass
    payload_event = args[0]['payload_event']
TypeError: tuple indices must be integers, not str

2017-10-06 04:11:40.966017 WARNING ------------------------------------------------------------
2017-10-06 04:12:16.752043 WARNING ------------------------------------------------------------
2017-10-06 04:12:16.755848 WARNING Unexpected error in worker for App Telegram:
2017-10-06 04:12:16.775470 WARNING Worker Ags: {'id': UUID('01c87726-cc1f-4c60-8459-073f4a7a2f09'), 'data': {'from_first': 'Legendary', 'from_last': 'Dav', 'text': 'Zone Bypass', 'user_id': 396287366, 'chat_id': 396287366}, 'name': 'Telegram', 'function': <bound method TelegramBotEventListener.receive_telegram_text of <telegram.TelegramBotEventListener object at 0xb5a7c4f0>>, 'type': 'event', 'event': 'telegram_text', 'kwargs': {}}
2017-10-06 04:12:16.779277 WARNING ------------------------------------------------------------
2017-10-06 04:12:16.809689 WARNING Traceback (most recent call last):
  File "/srv/homeassistant/lib/python3.4/site-packages/appdaemon/appdaemon.py", line 528, in worker
    function(args["event"], data, args["kwargs"])
  File "/home/homeassistant/config/appdaemon/apps/telegram.py", line 97, in receive_telegram_text
    simpleFunction(self, tuple([{'payload_event':payload_event,'accessgroup':accessgroup}]))
  File "/home/homeassistant/config/appdaemon/apps/telegram.py", line 198, in bypass
    payload_event = args[0]['payload_event']
TypeError: tuple indices must be integers, not str

2017-10-06 04:12:16.824749 WARNING ------------------------------------------------------------
2017-10-06 04:12:56.924422 WARNING ------------------------------------------------------------
2017-10-06 04:12:56.944761 WARNING Unexpected error in worker for App Telegram:
2017-10-06 04:12:56.948965 WARNING Worker Ags: {'id': UUID('01c87726-cc1f-4c60-8459-073f4a7a2f09'), 'data': {'from_first': 'Legendary', 'from_last': 'Dav', 'text': 'Alarm Functions', 'user_id': 396287366, 'chat_id': 396287366}, 'name': 'Telegram', 'function': <bound method TelegramBotEventListener.receive_telegram_text of <telegram.TelegramBotEventListener object at 0xb5a7c4f0>>, 'type': 'event', 'event': 'telegram_text', 'kwargs': {}}
2017-10-06 04:12:56.953049 WARNING ------------------------------------------------------------
2017-10-06 04:12:56.966330 WARNING Traceback (most recent call last):
  File "/srv/homeassistant/lib/python3.4/site-packages/appdaemon/appdaemon.py", line 528, in worker
    function(args["event"], data, args["kwargs"])
  File "/home/homeassistant/config/appdaemon/apps/telegram.py", line 97, in receive_telegram_text
    simpleFunction(self, tuple([{'payload_event':payload_event,'accessgroup':accessgroup}]))
TypeError: alarm_functions() missing 1 required positional argument: 'accessgroup'

2017-10-06 04:12:56.970037 WARNING ------------------------------------------------------------
2017-10-06 04:14:07.185658 WARNING ------------------------------------------------------------
2017-10-06 04:14:07.194758 WARNING Unexpected error in worker for App Telegram:
2017-10-06 04:14:07.198832 WARNING Worker Ags: {'id': UUID('941bfb3e-3796-472b-8dc4-b1f73ff78cbe'), 'data': {'from_first': 'Legendary', 'from_last': 'Dav', 'text': 'Zone Bypass', 'user_id': 396287366, 'chat_id': 396287366}, 'name': 'Telegram', 'function': <bound method TelegramBotEventListener.receive_telegram_text of <telegram.TelegramBotEventListener object at 0xb5794f90>>, 'type': 'event', 'event': 'telegram_text', 'kwargs': {}}
2017-10-06 04:14:07.209148 WARNING ------------------------------------------------------------
2017-10-06 04:14:07.220404 WARNING Traceback (most recent call last):
  File "/srv/homeassistant/lib/python3.4/site-packages/appdaemon/appdaemon.py", line 528, in worker
    function(args["event"], data, args["kwargs"])
  File "/home/homeassistant/config/appdaemon/apps/telegram.py", line 97, in receive_telegram_text
    simpleFunction(self, tuple({'payload_event':payload_event,'accessgroup':accessgroup}))
  File "/home/homeassistant/config/appdaemon/apps/telegram.py", line 198, in bypass
    payload_event = args[0]['payload_event']
TypeError: tuple indices must be integers, not str

2017-10-06 04:14:07.224772 WARNING ------------------------------------------------------------
2017-10-06 04:15:30.874918 WARNING ------------------------------------------------------------
2017-10-06 04:15:30.878630 WARNING Unexpected error in worker for App Telegram:
2017-10-06 04:15:30.885320 WARNING Worker Ags: {'id': UUID('b4c24315-e268-4ed6-b3d2-dd61253e03a0'), 'data': {'from_first': 'Legendary', 'from_last': 'Dav', 'text': 'Alarm Functions', 'user_id': 396287366, 'chat_id': 396287366}, 'name': 'Telegram', 'function': <bound method TelegramBotEventListener.receive_telegram_text of <telegram.TelegramBotEventListener object at 0xb597ac70>>, 'type': 'event', 'event': 'telegram_text', 'kwargs': {}}
2017-10-06 04:15:30.897605 WARNING ------------------------------------------------------------
2017-10-06 04:15:30.910900 WARNING Traceback (most recent call last):
  File "/srv/homeassistant/lib/python3.4/site-packages/appdaemon/appdaemon.py", line 528, in worker
    function(args["event"], data, args["kwargs"])
  File "/home/homeassistant/config/appdaemon/apps/telegram.py", line 97, in receive_telegram_text
    simpleFunction(self, tuple(payload_event,accessgroup))
TypeError: tuple() takes at most 1 argument (2 given)

2017-10-06 04:15:30.932650 WARNING ------------------------------------------------------------
2017-10-06 04:15:44.219680 WARNING ------------------------------------------------------------
2017-10-06 04:15:44.226084 WARNING Unexpected error in worker for App Telegram:
2017-10-06 04:15:44.240636 WARNING Worker Ags: {'id': UUID('b4c24315-e268-4ed6-b3d2-dd61253e03a0'), 'data': {'from_first': 'Legendary', 'from_last': 'Dav', 'text': 'Zone Bypass', 'user_id': 396287366, 'chat_id': 396287366}, 'name': 'Telegram', 'function': <bound method TelegramBotEventListener.receive_telegram_text of <telegram.TelegramBotEventListener object at 0xb597ac70>>, 'type': 'event', 'event': 'telegram_text', 'kwargs': {}}
2017-10-06 04:15:44.259959 WARNING ------------------------------------------------------------
2017-10-06 04:15:44.265600 WARNING Traceback (most recent call last):
  File "/srv/homeassistant/lib/python3.4/site-packages/appdaemon/appdaemon.py", line 528, in worker
    function(args["event"], data, args["kwargs"])
  File "/home/homeassistant/config/appdaemon/apps/telegram.py", line 97, in receive_telegram_text
    simpleFunction(self, tuple(payload_event,accessgroup))
TypeError: tuple() takes at most 1 argument (2 given)

2017-10-06 04:15:44.280585 WARNING ------------------------------------------------------------
2017-10-06 04:16:22.822375 WARNING ------------------------------------------------------------
2017-10-06 04:16:22.826105 WARNING Unexpected error in worker for App Telegram:
2017-10-06 04:16:22.835224 WARNING Worker Ags: {'id': UUID('d257f447-b872-4a06-ac47-a86f19f75c7f'), 'data': {'from_first': 'Legendary', 'from_last': 'Dav', 'text': 'Alarm Functions', 'user_id': 396287366, 'chat_id': 396287366}, 'name': 'Telegram', 'function': <bound method TelegramBotEventListener.receive_telegram_text of <telegram.TelegramBotEventListener object at 0xb57940f0>>, 'type': 'event', 'event': 'telegram_text', 'kwargs': {}}
2017-10-06 04:16:22.844738 WARNING ------------------------------------------------------------
2017-10-06 04:16:22.861207 WARNING Traceback (most recent call last):
  File "/srv/homeassistant/lib/python3.4/site-packages/appdaemon/appdaemon.py", line 528, in worker
    function(args["event"], data, args["kwargs"])
  File "/home/homeassistant/config/appdaemon/apps/telegram.py", line 97, in receive_telegram_text
    simpleFunction(self, tuple([payload_event,accessgroup]))
TypeError: alarm_functions() missing 1 required positional argument: 'accessgroup'

2017-10-06 04:16:22.874807 WARNING ------------------------------------------------------------
2017-10-06 04:16:31.292545 WARNING ------------------------------------------------------------
2017-10-06 04:16:31.305353 WARNING Unexpected error in worker for App Telegram:
2017-10-06 04:16:31.318175 WARNING Worker Ags: {'id': UUID('d257f447-b872-4a06-ac47-a86f19f75c7f'), 'data': {'from_first': 'Legendary', 'from_last': 'Dav', 'text': 'Zone Bypass', 'user_id': 396287366, 'chat_id': 396287366}, 'name': 'Telegram', 'function': <bound method TelegramBotEventListener.receive_telegram_text of <telegram.TelegramBotEventListener object at 0xb57940f0>>, 'type': 'event', 'event': 'telegram_text', 'kwargs': {}}
2017-10-06 04:16:31.328846 WARNING ------------------------------------------------------------
2017-10-06 04:16:31.337494 WARNING Traceback (most recent call last):
  File "/srv/homeassistant/lib/python3.4/site-packages/appdaemon/appdaemon.py", line 528, in worker
    function(args["event"], data, args["kwargs"])
  File "/home/homeassistant/config/appdaemon/apps/telegram.py", line 97, in receive_telegram_text
    simpleFunction(self, tuple([payload_event,accessgroup]))
  File "/home/homeassistant/config/appdaemon/apps/telegram.py", line 198, in bypass
    payload_event = args[0]['payload_event']
TypeError: tuple indices must be integers, not str

2017-10-06 04:16:31.351286 WARNING ------------------------------------------------------------
2017-10-06 04:17:33.677224 WARNING ------------------------------------------------------------
2017-10-06 04:17:33.680786 WARNING Unexpected error in worker for App Telegram:
2017-10-06 04:17:33.689810 WARNING Worker Ags: {'id': UUID('276de236-adc8-4b76-8566-e86384cf6f82'), 'data': {'from_first': 'Legendary', 'from_last': 'Dav', 'text': 'Zone Bypass', 'user_id': 396287366, 'chat_id': 396287366}, 'name': 'Telegram', 'function': <bound method TelegramBotEventListener.receive_telegram_text of <telegram.TelegramBotEventListener object at 0xb5a53950>>, 'type': 'event', 'event': 'telegram_text', 'kwargs': {}}
2017-10-06 04:17:33.704799 WARNING ------------------------------------------------------------
2017-10-06 04:17:33.716804 WARNING Traceback (most recent call last):
  File "/srv/homeassistant/lib/python3.4/site-packages/appdaemon/appdaemon.py", line 528, in worker
    function(args["event"], data, args["kwargs"])
  File "/home/homeassistant/config/appdaemon/apps/telegram.py", line 97, in receive_telegram_text
    simpleFunction(self, payload = payload_event, accessgroup = accessgroup)
TypeError: bypass() got an unexpected keyword argument 'payload'

2017-10-06 04:17:33.727054 WARNING ------------------------------------------------------------
2017-10-06 04:17:57.365461 WARNING ------------------------------------------------------------
2017-10-06 04:17:57.374823 WARNING Unexpected error in worker for App Telegram:
2017-10-06 04:17:57.379153 WARNING Worker Ags: {'id': UUID('ae035af4-5a58-4096-8295-048b17066189'), 'data': {'from_first': 'Legendary', 'from_last': 'Dav', 'text': 'Zone Bypass', 'user_id': 396287366, 'chat_id': 396287366}, 'name': 'Telegram', 'function': <bound method TelegramBotEventListener.receive_telegram_text of <telegram.TelegramBotEventListener object at 0xb5a9deb0>>, 'type': 'event', 'event': 'telegram_text', 'kwargs': {}}
2017-10-06 04:17:57.388213 WARNING ------------------------------------------------------------
2017-10-06 04:17:57.403164 WARNING Traceback (most recent call last):
  File "/srv/homeassistant/lib/python3.4/site-packages/appdaemon/appdaemon.py", line 528, in worker
    function(args["event"], data, args["kwargs"])
  File "/home/homeassistant/config/appdaemon/apps/telegram.py", line 97, in receive_telegram_text
    simpleFunction(self, payload_event = payload_event, accessgroup = accessgroup)
TypeError: bypass() got an unexpected keyword argument 'payload_event'

2017-10-06 04:17:57.424752 WARNING ------------------------------------------------------------
2017-10-06 04:20:31.824803 WARNING ------------------------------------------------------------
2017-10-06 04:20:31.828598 WARNING Unexpected error in worker for App Telegram:
2017-10-06 04:20:31.832549 WARNING Worker Ags: {'id': UUID('95ee335b-c241-466f-ab4f-63f69eca38cc'), 'data': {'from_first': 'Legendary', 'from_last': 'Dav', 'text': 'Zone Bypass', 'user_id': 396287366, 'chat_id': 396287366}, 'name': 'Telegram', 'function': <bound method TelegramBotEventListener.receive_telegram_text of <telegram.TelegramBotEventListener object at 0xb597a1d0>>, 'type': 'event', 'event': 'telegram_text', 'kwargs': {}}
2017-10-06 04:20:31.842684 WARNING ------------------------------------------------------------
2017-10-06 04:20:31.858744 WARNING Traceback (most recent call last):
  File "/srv/homeassistant/lib/python3.4/site-packages/appdaemon/appdaemon.py", line 528, in worker
    function(args["event"], data, args["kwargs"])
  File "/home/homeassistant/config/appdaemon/apps/telegram.py", line 97, in receive_telegram_text
    simpleFunction(self, payload_event, accessgroup)
  File "/home/homeassistant/config/appdaemon/apps/telegram.py", line 198, in bypass
    payload_event = args[0]['payload_event']
KeyError: 'payload_event'

2017-10-06 04:20:31.874221 WARNING ------------------------------------------------------------
2017-10-06 04:26:11.084799 WARNING ------------------------------------------------------------
2017-10-06 04:26:11.094936 WARNING Unexpected error in worker for App Telegram:
2017-10-06 04:26:11.099332 WARNING Worker Ags: {'id': UUID('2de25b8c-532c-4dc7-b5c0-59de173b4163'), 'type': 'timer', 'name': 'Telegram', 'function': <bound method TelegramBotEventListener.bypass of <telegram.TelegramBotEventListener object at 0xb599c870>>, 'kwargs': {'accessgroup': {'chatids': ['444908880', '396287366'], 'scenes': ['script.new'], 'lights': ['switch.kitchen', 'switch.living_room', 'switch.dummy', 'switch.tarinis_bedroom', 'light.lamp', 'light.lounge', 'light.gateway_light_34ce0088d613'], 'groupname': 'admin', 'rooms': ['group.living_room', 'group.bathroom', 'group.bedroom', 'group.kitchen'], 'menu': ['Alarm Functions', 'Rooms', 'Lights,Switches,Scenes', 'Cameras'], 'alarm': {'functions': ['nonee']}, 'switches': ['switch.tv', 'switch.living_room_outlet_2', 'switch.kettle', 'switch.bedroom_outlet']}, 'payload_event': {'from_first': 'Legendary', 'from_last': 'Dav', 'text': 'bypass downstairs', 'user_id': 396287366, 'chat_id': 396287366}}}
2017-10-06 04:26:11.114749 WARNING ------------------------------------------------------------
2017-10-06 04:26:11.125385 WARNING Traceback (most recent call last):
  File "/srv/homeassistant/lib/python3.4/site-packages/appdaemon/appdaemon.py", line 518, in worker
    function(ha.sanitize_timer_kwargs(args["kwargs"]))
  File "/home/homeassistant/config/appdaemon/apps/telegram.py", line 199, in bypass
    accessgroup = args[1]
IndexError: tuple index out of range

2017-10-06 04:26:11.134741 WARNING ------------------------------------------------------------
2017-10-06 04:27:54.488337 WARNING ------------------------------------------------------------
2017-10-06 04:27:54.493265 WARNING Unexpected error in worker for App Telegram:
2017-10-06 04:27:54.511302 WARNING Worker Ags: {'id': UUID('a6074ced-8acc-4341-aaae-60a4e2495687'), 'data': {'from_first': 'Legendary', 'from_last': 'Dav', 'text': 'bypass downstairs', 'user_id': 396287366, 'chat_id': 396287366}, 'name': 'Telegram', 'function': <bound method TelegramBotEventListener.receive_telegram_text of <telegram.TelegramBotEventListener object at 0xb599ce30>>, 'type': 'event', 'event': 'telegram_text', 'kwargs': {}}
2017-10-06 04:27:54.515614 WARNING ------------------------------------------------------------
2017-10-06 04:27:54.527495 WARNING Traceback (most recent call last):
  File "/srv/homeassistant/lib/python3.4/site-packages/appdaemon/appdaemon.py", line 528, in worker
    function(args["event"], data, args["kwargs"])
  File "/home/homeassistant/config/appdaemon/apps/telegram.py", line 107, in receive_telegram_text
    self.bypassZone(payload_event, accessgroup)
  File "/home/homeassistant/config/appdaemon/apps/telegram.py", line 192, in bypassZone
    self.run_in(self.bypass,15,payload_event, accessgroup)
TypeError: run_in() takes 3 positional arguments but 5 were given

2017-10-06 04:27:54.531870 WARNING ------------------------------------------------------------
2017-10-06 04:30:47.154808 WARNING ------------------------------------------------------------
2017-10-06 04:30:47.162957 WARNING Unexpected error in worker for App Telegram:
2017-10-06 04:30:47.172632 WARNING Worker Ags: {'id': UUID('168fe089-e27d-45c7-9032-b086fab96463'), 'type': 'timer', 'name': 'Telegram', 'function': <bound method TelegramBotEventListener.bypass of <telegram.TelegramBotEventListener object at 0xb5a530b0>>, 'kwargs': {'accessgroup': {'chatids': ['444908880', '396287366'], 'scenes': ['script.new'], 'lights': ['switch.kitchen', 'switch.living_room', 'switch.dummy', 'switch.tarinis_bedroom', 'light.lamp', 'light.lounge', 'light.gateway_light_34ce0088d613'], 'groupname': 'admin', 'rooms': ['group.living_room', 'group.bathroom', 'group.bedroom', 'group.kitchen'], 'menu': ['Alarm Functions', 'Rooms', 'Lights,Switches,Scenes', 'Cameras'], 'alarm': {'functions': ['nonee']}, 'switches': ['switch.tv', 'switch.living_room_outlet_2', 'switch.kettle', 'switch.bedroom_outlet']}, 'payload_event': {'from_first': 'Legendary', 'from_last': 'Dav', 'text': 'bypass downstairs', 'user_id': 396287366, 'chat_id': 396287366}}}
2017-10-06 04:30:47.186972 WARNING ------------------------------------------------------------
2017-10-06 04:30:47.201256 WARNING Traceback (most recent call last):
  File "/srv/homeassistant/lib/python3.4/site-packages/appdaemon/appdaemon.py", line 518, in worker
    function(ha.sanitize_timer_kwargs(args["kwargs"]))
  File "/home/homeassistant/config/appdaemon/apps/telegram.py", line 199, in bypass
    accessgroup = args[1]
IndexError: tuple index out of range

2017-10-06 04:30:47.224555 WARNING ------------------------------------------------------------
2017-10-06 04:42:52.041739 WARNING ------------------------------------------------------------
2017-10-06 04:42:52.052656 WARNING Unexpected error during loading of telegram.py:
2017-10-06 04:42:52.057141 WARNING ------------------------------------------------------------
2017-10-06 04:42:52.064046 WARNING Traceback (most recent call last):
  File "/srv/homeassistant/lib/python3.4/site-packages/appdaemon/appdaemon.py", line 903, in read_app
    importlib.reload(conf.modules[module_name])
  File "/srv/homeassistant/lib/python3.4/importlib/__init__.py", line 149, in reload
    methods.exec(module)
  File "<frozen importlib._bootstrap>", line 1153, in exec
  File "<frozen importlib._bootstrap>", line 1129, in _exec
  File "<frozen importlib._bootstrap>", line 1467, in exec_module
  File "<frozen importlib._bootstrap>", line 1572, in get_code
  File "<frozen importlib._bootstrap>", line 1532, in source_to_code
  File "<frozen importlib._bootstrap>", line 321, in _call_with_frames_removed
  File "/home/homeassistant/config/appdaemon/apps/telegram.py", line 5
    keyboard.append("{} Menu,{} Alarm Functions".format(u'\U0001f3e0',u'\U0001f448'))
    ^
IndentationError: unexpected indent

2017-10-06 04:42:52.068395 WARNING ------------------------------------------------------------
2017-10-06 04:42:53.043304 WARNING ------------------------------------------------------------
2017-10-06 04:42:53.052915 WARNING Unexpected error during loading of telegram.py:
2017-10-06 04:42:53.057698 WARNING ------------------------------------------------------------
2017-10-06 04:42:53.064508 WARNING Traceback (most recent call last):
  File "/srv/homeassistant/lib/python3.4/site-packages/appdaemon/appdaemon.py", line 903, in read_app
    importlib.reload(conf.modules[module_name])
  File "/srv/homeassistant/lib/python3.4/importlib/__init__.py", line 149, in reload
    methods.exec(module)
  File "<frozen importlib._bootstrap>", line 1153, in exec
  File "<frozen importlib._bootstrap>", line 1129, in _exec
  File "<frozen importlib._bootstrap>", line 1467, in exec_module
  File "<frozen importlib._bootstrap>", line 1572, in get_code
  File "<frozen importlib._bootstrap>", line 1532, in source_to_code
  File "<frozen importlib._bootstrap>", line 321, in _call_with_frames_removed
  File "/home/homeassistant/config/appdaemon/apps/telegram.py", line 5
    keyboard.append("{} Menu,{} Alarm Functions".format(u'\U0001f3e0',u'\U0001f448'))
    ^
IndentationError: unexpected indent

2017-10-06 04:42:53.068442 WARNING ------------------------------------------------------------
2017-10-06 04:43:05.032409 WARNING ------------------------------------------------------------
2017-10-06 04:43:05.047593 WARNING Unexpected error during loading of telegram.py:
2017-10-06 04:43:05.051557 WARNING ------------------------------------------------------------
2017-10-06 04:43:05.058834 WARNING Traceback (most recent call last):
  File "/srv/homeassistant/lib/python3.4/site-packages/appdaemon/appdaemon.py", line 903, in read_app
    importlib.reload(conf.modules[module_name])
  File "/srv/homeassistant/lib/python3.4/importlib/__init__.py", line 149, in reload
    methods.exec(module)
  File "<frozen importlib._bootstrap>", line 1153, in exec
  File "<frozen importlib._bootstrap>", line 1129, in _exec
  File "<frozen importlib._bootstrap>", line 1467, in exec_module
  File "<frozen importlib._bootstrap>", line 1572, in get_code
  File "<frozen importlib._bootstrap>", line 1532, in source_to_code
  File "<frozen importlib._bootstrap>", line 321, in _call_with_frames_removed
  File "/home/homeassistant/config/appdaemon/apps/telegram.py", line 15
    "Disarm".format(u'\U0001f513')									: 'disarm',
                                  									^
SyntaxError: invalid syntax

2017-10-06 04:43:05.062846 WARNING ------------------------------------------------------------
2017-10-06 04:43:06.032421 WARNING ------------------------------------------------------------
2017-10-06 04:43:06.047686 WARNING Unexpected error during loading of telegram.py:
2017-10-06 04:43:06.051637 WARNING ------------------------------------------------------------
2017-10-06 04:43:06.058685 WARNING Traceback (most recent call last):
  File "/srv/homeassistant/lib/python3.4/site-packages/appdaemon/appdaemon.py", line 903, in read_app
    importlib.reload(conf.modules[module_name])
  File "/srv/homeassistant/lib/python3.4/importlib/__init__.py", line 149, in reload
    methods.exec(module)
  File "<frozen importlib._bootstrap>", line 1153, in exec
  File "<frozen importlib._bootstrap>", line 1129, in _exec
  File "<frozen importlib._bootstrap>", line 1467, in exec_module
  File "<frozen importlib._bootstrap>", line 1572, in get_code
  File "<frozen importlib._bootstrap>", line 1532, in source_to_code
  File "<frozen importlib._bootstrap>", line 321, in _call_with_frames_removed
  File "/home/homeassistant/config/appdaemon/apps/telegram.py", line 15
    "Disarm".format(u'\U0001f513')									: 'disarm',
                                  									^
SyntaxError: invalid syntax

2017-10-06 04:43:06.062945 WARNING ------------------------------------------------------------
2017-10-06 04:44:37.198143 WARNING ------------------------------------------------------------
2017-10-06 04:44:37.201802 WARNING Unexpected error in worker for App Telegram:
2017-10-06 04:44:37.214640 WARNING Worker Ags: {'id': UUID('f8e39cd2-1601-460f-9f8f-574e9f3de7d7'), 'data': {'from_first': 'Legendary', 'from_last': 'Dav', 'text': '👈 Alarm Functions', 'user_id': 396287366, 'chat_id': 396287366}, 'name': 'Telegram', 'function': <bound method TelegramBotEventListener.receive_telegram_text of <telegram.TelegramBotEventListener object at 0xb5a7ccd0>>, 'type': 'event', 'event': 'telegram_text', 'kwargs': {}}
2017-10-06 04:44:37.218498 WARNING ------------------------------------------------------------
2017-10-06 04:44:37.238653 WARNING Traceback (most recent call last):
  File "/srv/homeassistant/lib/python3.4/site-packages/appdaemon/appdaemon.py", line 528, in worker
    function(args["event"], data, args["kwargs"])
  File "/home/homeassistant/config/appdaemon/apps/telegram.py", line 100, in receive_telegram_text
    simpleFunction(self, payload_event, accessgroup)
  File "/home/homeassistant/config/appdaemon/apps/telegram.py", line 253, in alarm_functions
    keyboard = self.getKeyboard(alarm_state['state'],accessgroup,payload_event))
  File "/home/homeassistant/config/appdaemon/apps/telegram.py", line 390, in getKeyboard
    keyboard = self.getRefinedKeyboard(KEYBOARD_STRUCTURE[keyboard_type],accessgroup['alarm']['functions'])
  File "/home/homeassistant/config/appdaemon/apps/telegram.py", line 400, in getRefinedKeyboard
    line = ALARM_KEYBOARD[item[0]]
KeyError: 'backToMenu'

2017-10-06 04:44:37.251957 WARNING ------------------------------------------------------------
2017-10-06 04:48:26.787450 WARNING ------------------------------------------------------------
2017-10-06 04:48:26.791988 WARNING Unexpected error in worker for App Telegram:
2017-10-06 04:48:26.802794 WARNING Worker Ags: {'id': UUID('8866282f-c726-46c1-9584-f5a21fcb8d92'), 'data': {'from_first': 'Legendary', 'from_last': 'Dav', 'text': '👈 Alarm Functions', 'user_id': 396287366, 'chat_id': 396287366}, 'name': 'Telegram', 'function': <bound method TelegramBotEventListener.receive_telegram_text of <telegram.TelegramBotEventListener object at 0xb597a730>>, 'type': 'event', 'event': 'telegram_text', 'kwargs': {}}
2017-10-06 04:48:26.807804 WARNING ------------------------------------------------------------
2017-10-06 04:48:26.835505 WARNING Traceback (most recent call last):
  File "/srv/homeassistant/lib/python3.4/site-packages/appdaemon/appdaemon.py", line 528, in worker
    function(args["event"], data, args["kwargs"])
  File "/home/homeassistant/config/appdaemon/apps/telegram.py", line 100, in receive_telegram_text
    simpleFunction(self, payload_event, accessgroup)
  File "/home/homeassistant/config/appdaemon/apps/telegram.py", line 253, in alarm_functions
    keyboard = self.getKeyboard(alarm_state['state'],accessgroup,payload_event))
  File "/home/homeassistant/config/appdaemon/apps/telegram.py", line 390, in getKeyboard
    keyboard = self.getRefinedKeyboard(KEYBOARD_STRUCTURE[keyboard_type],accessgroup['alarm']['functions'])
  File "/home/homeassistant/config/appdaemon/apps/telegram.py", line 401, in getRefinedKeyboard
    line = ALARM_KEYBOARD[item[0]]
KeyError: 'backToMenu'

2017-10-06 04:48:26.855051 WARNING ------------------------------------------------------------
2017-10-06 04:50:12.805110 WARNING ------------------------------------------------------------
2017-10-06 04:50:12.819894 WARNING Unexpected error in worker for App Alarm:
2017-10-06 04:50:12.826198 WARNING Worker Ags: {'id': UUID('3917c45f-4371-4d17-9d75-a834abec83bc'), 'data': {'old_state': {'last_updated': '2017-10-06T02:44:33.521787+00:00', 'entity_id': 'alarm_control_panel.house', 'attributes': {'friendly_name': 'House', 'immediate': ['binary_sensor.door_window_sensor_158d000187120a'], 'zones': ['group.zone_downstairs', 'group.zone_garage', 'group.zone_kitchen', 'group.zone_living_room', 'group.zone_outside', 'group.zone_upstairs'], 'changed_by': '', 'ignored': ['binary_sensor.motion_sensor_158d00016dcfa8'], 'bypassedsensors': [], 'code_format': None, 'triggeredBy': "{'name': 'Legendary', 'chat_id': '396287366'}", 'delayed': ['binary_sensor.switch_158d000186e9bd'], 'changedby': '', 'trippedsensors': [], 'allsensors': ['binary_sensor.door_window_sensor_158d000187120a', 'binary_sensor.motion_sensor_158d00016dcfa8', 'binary_sensor.switch_158d000186e9bd']}, 'state': 'armed_home', 'last_changed': '2017-10-06T00:47:52.099296+00:00'}, 'entity_id': 'alarm_control_panel.house', 'new_state': {'last_updated': '2017-10-06T02:50:12.040232+00:00', 'entity_id': 'alarm_control_panel.house', 'attributes': {'friendly_name': 'House', 'immediate': [], 'zones': ['group.zone_downstairs', 'group.zone_garage', 'group.zone_kitchen', 'group.zone_living_room', 'group.zone_outside', 'group.zone_upstairs'], 'changed_by': '', 'ignored': ['binary_sensor.door_window_sensor_158d000187120a', 'binary_sensor.motion_sensor_158d00016dcfa8', 'binary_sensor.switch_158d000186e9bd'], 'bypassedsensors': [], 'code_format': None, 'triggeredBy': "{'name': 'Legendary', 'chat_id': '396287366'}", 'delayed': [], 'changedby': '', 'trippedsensors': [], 'allsensors': ['binary_sensor.door_window_sensor_158d000187120a', 'binary_sensor.motion_sensor_158d00016dcfa8', 'binary_sensor.switch_158d000186e9bd']}, 'state': 'disarmed', 'last_changed': '2017-10-06T02:50:12.040232+00:00'}}, 'name': 'Alarm', 'function': <bound method AlarmReaction.alarmListener of <alarm.AlarmReaction object at 0xb5b306d0>>, 'type': 'event', 'event': 'state_changed', 'kwargs': {'entity_id': 'alarm_control_panel.house'}}
2017-10-06 04:50:12.844777 WARNING ------------------------------------------------------------
2017-10-06 04:50:12.862343 WARNING Traceback (most recent call last):
  File "/srv/homeassistant/lib/python3.4/site-packages/appdaemon/appdaemon.py", line 528, in worker
    function(args["event"], data, args["kwargs"])
  File "/home/homeassistant/config/appdaemon/apps/alarm.py", line 17, in alarmListener
    self.trigger(data,kwargs)
  File "/home/homeassistant/config/appdaemon/apps/alarm.py", line 29, in trigger
    self.telegram_notify(new_state, triggered_by)
  File "/home/homeassistant/config/appdaemon/apps/alarm.py", line 52, in telegram_notify
    keyboard = self.telegram.getKeyboard(new_state,accessgroup)
  File "/home/homeassistant/config/appdaemon/apps/telegram.py", line 373, in getKeyboard
    keyboard.append("{} Back to Menu".format(u'\U0001f3e0'))
  File "/home/homeassistant/config/appdaemon/apps/telegram.py", line 381, in getRefinedKeyboard
    friendly_name_temp = str(self.get_state(entity,"friendly_name"))
KeyError: 'armStay'

2017-10-06 04:50:12.884819 WARNING ------------------------------------------------------------
2017-10-06 05:00:09.060392 WARNING ------------------------------------------------------------
2017-10-06 05:00:09.064497 WARNING Unexpected error during loading of telegram.py:
2017-10-06 05:00:09.068052 WARNING ------------------------------------------------------------
2017-10-06 05:00:09.074892 WARNING Traceback (most recent call last):
  File "/srv/homeassistant/lib/python3.4/site-packages/appdaemon/appdaemon.py", line 903, in read_app
    importlib.reload(conf.modules[module_name])
  File "/srv/homeassistant/lib/python3.4/importlib/__init__.py", line 149, in reload
    methods.exec(module)
  File "<frozen importlib._bootstrap>", line 1153, in exec
  File "<frozen importlib._bootstrap>", line 1129, in _exec
  File "<frozen importlib._bootstrap>", line 1467, in exec_module
  File "<frozen importlib._bootstrap>", line 1572, in get_code
  File "<frozen importlib._bootstrap>", line 1532, in source_to_code
  File "<frozen importlib._bootstrap>", line 321, in _call_with_frames_removed
  File "/home/homeassistant/config/appdaemon/apps/telegram.py", line 179
    =		sensors = None
    ^
SyntaxError: invalid syntax

2017-10-06 05:00:09.078831 WARNING ------------------------------------------------------------
2017-10-06 05:00:11.059008 WARNING ------------------------------------------------------------
2017-10-06 05:00:11.062655 WARNING Unexpected error during loading of telegram.py:
2017-10-06 05:00:11.066518 WARNING ------------------------------------------------------------
2017-10-06 05:00:11.073305 WARNING Traceback (most recent call last):
  File "/srv/homeassistant/lib/python3.4/site-packages/appdaemon/appdaemon.py", line 903, in read_app
    importlib.reload(conf.modules[module_name])
  File "/srv/homeassistant/lib/python3.4/importlib/__init__.py", line 149, in reload
    methods.exec(module)
  File "<frozen importlib._bootstrap>", line 1153, in exec
  File "<frozen importlib._bootstrap>", line 1129, in _exec
  File "<frozen importlib._bootstrap>", line 1467, in exec_module
  File "<frozen importlib._bootstrap>", line 1572, in get_code
  File "<frozen importlib._bootstrap>", line 1532, in source_to_code
  File "<frozen importlib._bootstrap>", line 321, in _call_with_frames_removed
  File "/home/homeassistant/config/appdaemon/apps/telegram.py", line 179
    =		sensors = None
    ^
SyntaxError: invalid syntax

2017-10-06 05:00:11.077323 WARNING ------------------------------------------------------------
2017-10-06 05:04:16.817562 WARNING ------------------------------------------------------------
2017-10-06 05:04:16.821130 WARNING Unexpected error in worker for App Telegram:
2017-10-06 05:04:16.829391 WARNING Worker Ags: {'id': UUID('55788403-7bf0-48d8-b2a7-4d5b6603989a'), 'data': {'from_first': 'Legendary', 'from_last': 'Dav', 'text': 'downstairs sensors', 'user_id': 396287366, 'chat_id': 396287366}, 'name': 'Telegram', 'function': <bound method TelegramBotEventListener.receive_telegram_text of <telegram.TelegramBotEventListener object at 0xb5a9d670>>, 'type': 'event', 'event': 'telegram_text', 'kwargs': {}}
2017-10-06 05:04:16.833295 WARNING ------------------------------------------------------------
2017-10-06 05:04:16.850656 WARNING Traceback (most recent call last):
  File "/srv/homeassistant/lib/python3.4/site-packages/appdaemon/appdaemon.py", line 528, in worker
    function(args["event"], data, args["kwargs"])
  File "/home/homeassistant/config/appdaemon/apps/telegram.py", line 116, in receive_telegram_text
    self.sensorStatusSelective(payload_event, accessgroup)
  File "/home/homeassistant/config/appdaemon/apps/telegram.py", line 184, in sensorStatusSelective
    if friendly_name_text == friendly_name_test:
NameError: name 'friendly_name_text' is not defined

2017-10-06 05:04:16.864964 WARNING ------------------------------------------------------------
2017-10-06 05:04:41.358206 WARNING ------------------------------------------------------------
2017-10-06 05:04:41.374763 WARNING Unexpected error in worker for App Telegram:
2017-10-06 05:04:41.378810 WARNING Worker Ags: {'id': UUID('63124dfc-085a-4b99-a361-2a1d4cc89047'), 'data': {'from_first': 'Legendary', 'from_last': 'Dav', 'text': 'downstairs sensors', 'user_id': 396287366, 'chat_id': 396287366}, 'name': 'Telegram', 'function': <bound method TelegramBotEventListener.receive_telegram_text of <telegram.TelegramBotEventListener object at 0xb5a9ddd0>>, 'type': 'event', 'event': 'telegram_text', 'kwargs': {}}
2017-10-06 05:04:41.382857 WARNING ------------------------------------------------------------
2017-10-06 05:04:41.407770 WARNING Traceback (most recent call last):
  File "/srv/homeassistant/lib/python3.4/site-packages/appdaemon/appdaemon.py", line 528, in worker
    function(args["event"], data, args["kwargs"])
  File "/home/homeassistant/config/appdaemon/apps/telegram.py", line 116, in receive_telegram_text
    self.sensorStatusSelective(payload_event, accessgroup)
  File "/home/homeassistant/config/appdaemon/apps/telegram.py", line 184, in sensorStatusSelective
    if friendly_name_text == friendly_name_test:
NameError: name 'friendly_name_test' is not defined

2017-10-06 05:04:41.411919 WARNING ------------------------------------------------------------
2017-10-06 05:04:54.869274 WARNING ------------------------------------------------------------
2017-10-06 05:04:54.873024 WARNING Unexpected error in worker for App Telegram:
2017-10-06 05:04:54.879073 WARNING Worker Ags: {'id': UUID('e8dfb439-8c17-4665-9a01-179f55ca6d68'), 'data': {'from_first': 'Legendary', 'from_last': 'Dav', 'text': 'downstairs sensors', 'user_id': 396287366, 'chat_id': 396287366}, 'name': 'Telegram', 'function': <bound method TelegramBotEventListener.receive_telegram_text of <telegram.TelegramBotEventListener object at 0xb5938df0>>, 'type': 'event', 'event': 'telegram_text', 'kwargs': {}}
2017-10-06 05:04:54.894445 WARNING ------------------------------------------------------------
2017-10-06 05:04:54.915578 WARNING Traceback (most recent call last):
  File "/srv/homeassistant/lib/python3.4/site-packages/appdaemon/appdaemon.py", line 528, in worker
    function(args["event"], data, args["kwargs"])
  File "/home/homeassistant/config/appdaemon/apps/telegram.py", line 116, in receive_telegram_text
    self.sensorStatusSelective(payload_event, accessgroup)
  File "/home/homeassistant/config/appdaemon/apps/telegram.py", line 184, in sensorStatusSelective
    if friendly_name_text == friendly_name_test:
NameError: name 'friendly_name_test' is not defined

2017-10-06 05:04:54.919537 WARNING ------------------------------------------------------------
2017-10-06 05:13:50.293557 WARNING ------------------------------------------------------------
2017-10-06 05:13:50.311223 WARNING Unexpected error in worker for App Telegram:
2017-10-06 05:13:50.318913 WARNING Worker Ags: {'id': UUID('e30f7034-b527-49d2-8d93-1bf8dc0f2124'), 'data': {'from_first': 'Legendary', 'from_last': 'Dav', 'text': 'enable downstairs', 'user_id': 396287366, 'chat_id': 396287366}, 'name': 'Telegram', 'function': <bound method TelegramBotEventListener.receive_telegram_text of <telegram.TelegramBotEventListener object at 0xb5794db0>>, 'type': 'event', 'event': 'telegram_text', 'kwargs': {}}
2017-10-06 05:13:50.334744 WARNING ------------------------------------------------------------
2017-10-06 05:13:50.346238 WARNING Traceback (most recent call last):
  File "/srv/homeassistant/lib/python3.4/site-packages/appdaemon/appdaemon.py", line 528, in worker
    function(args["event"], data, args["kwargs"])
  File "/home/homeassistant/config/appdaemon/apps/telegram.py", line 112, in receive_telegram_text
    self.bypassZone(payload_event, accessgroup)
  File "/home/homeassistant/config/appdaemon/apps/telegram.py", line 215, in bypassZone
    handle = self.call_service("alarm_control_panel/alarm_arm_{}_zone".format(ALARM_KEYBOARD[splitText[0]]),zone = entity_id)
KeyError: 'enable'

2017-10-06 05:13:50.354740 WARNING ------------------------------------------------------------
2017-10-06 05:16:05.382342 WARNING ------------------------------------------------------------
2017-10-06 05:16:05.416137 WARNING Unexpected error in worker for App Alarm:
2017-10-06 05:16:05.420752 WARNING Worker Ags: {'id': UUID('3917c45f-4371-4d17-9d75-a834abec83bc'), 'data': {'old_state': {'last_updated': '2017-10-06T03:15:54.086330+00:00', 'entity_id': 'alarm_control_panel.house', 'attributes': {'friendly_name': 'House', 'immediate': [], 'zones': ['group.zone_downstairs', 'group.zone_garage', 'group.zone_kitchen', 'group.zone_living_room', 'group.zone_outside', 'group.zone_upstairs'], 'changed_by': '', 'ignored': ['binary_sensor.door_window_sensor_158d000187120a', 'binary_sensor.motion_sensor_158d00016dcfa8', 'binary_sensor.switch_158d000186e9bd'], 'bypassedsensors': ['binary_sensor.switch_158d000186e9bd'], 'code_format': None, 'triggeredBy': "{'name': 'Legendary', 'chat_id': '396287366'}", 'delayed': [], 'changedby': '', 'trippedsensors': [], 'allsensors': ['binary_sensor.door_window_sensor_158d000187120a', 'binary_sensor.motion_sensor_158d00016dcfa8', 'binary_sensor.switch_158d000186e9bd']}, 'state': 'disarmed', 'last_changed': '2017-10-06T02:50:12.040232+00:00'}, 'entity_id': 'alarm_control_panel.house', 'new_state': {'last_updated': '2017-10-06T03:16:04.699603+00:00', 'entity_id': 'alarm_control_panel.house', 'attributes': {'friendly_name': 'House', 'immediate': ['binary_sensor.door_window_sensor_158d000187120a'], 'zones': ['group.zone_downstairs', 'group.zone_garage', 'group.zone_kitchen', 'group.zone_living_room', 'group.zone_outside', 'group.zone_upstairs'], 'changed_by': '', 'ignored': ['binary_sensor.motion_sensor_158d00016dcfa8'], 'bypassedsensors': ['binary_sensor.switch_158d000186e9bd'], 'code_format': None, 'triggeredBy': "{'name': 'Legendary', 'chat_id': '396287366'}", 'delayed': ['binary_sensor.switch_158d000186e9bd'], 'changedby': '', 'trippedsensors': [], 'allsensors': ['binary_sensor.door_window_sensor_158d000187120a', 'binary_sensor.motion_sensor_158d00016dcfa8', 'binary_sensor.switch_158d000186e9bd']}, 'state': 'armed_home', 'last_changed': '2017-10-06T03:16:04.699603+00:00'}}, 'name': 'Alarm', 'function': <bound method AlarmReaction.alarmListener of <alarm.AlarmReaction object at 0xb5b306d0>>, 'type': 'event', 'event': 'state_changed', 'kwargs': {'entity_id': 'alarm_control_panel.house'}}
2017-10-06 05:16:05.425569 WARNING ------------------------------------------------------------
2017-10-06 05:16:05.464564 WARNING Traceback (most recent call last):
  File "/srv/homeassistant/lib/python3.4/site-packages/appdaemon/appdaemon.py", line 528, in worker
    function(args["event"], data, args["kwargs"])
  File "/home/homeassistant/config/appdaemon/apps/alarm.py", line 17, in alarmListener
    self.trigger(data,kwargs)
  File "/home/homeassistant/config/appdaemon/apps/alarm.py", line 29, in trigger
    self.telegram_notify(new_state, triggered_by)
  File "/home/homeassistant/config/appdaemon/apps/alarm.py", line 52, in telegram_notify
    keyboard = self.telegram.getKeyboard(new_state,accessgroup)
  File "/home/homeassistant/config/appdaemon/apps/telegram.py", line 373, in getKeyboard
    self.call_service("telegram_bot/send_message",
  File "/home/homeassistant/config/appdaemon/apps/telegram.py", line 381, in getRefinedKeyboard
    self.call_service("homeassistant/turn_off", entity_id = entity_id)
KeyError: 'disarm'

2017-10-06 05:16:05.478531 WARNING ------------------------------------------------------------
2017-10-06 05:16:20.322682 WARNING ------------------------------------------------------------
2017-10-06 05:16:20.334743 WARNING Unexpected error in worker for App Alarm:
2017-10-06 05:16:20.339351 WARNING Worker Ags: {'id': UUID('3917c45f-4371-4d17-9d75-a834abec83bc'), 'data': {'old_state': {'last_updated': '2017-10-06T03:16:04.699603+00:00', 'entity_id': 'alarm_control_panel.house', 'attributes': {'friendly_name': 'House', 'immediate': ['binary_sensor.door_window_sensor_158d000187120a'], 'zones': ['group.zone_downstairs', 'group.zone_garage', 'group.zone_kitchen', 'group.zone_living_room', 'group.zone_outside', 'group.zone_upstairs'], 'changed_by': '', 'ignored': ['binary_sensor.motion_sensor_158d00016dcfa8'], 'bypassedsensors': ['binary_sensor.switch_158d000186e9bd'], 'code_format': None, 'triggeredBy': "{'name': 'Legendary', 'chat_id': '396287366'}", 'delayed': ['binary_sensor.switch_158d000186e9bd'], 'changedby': '', 'trippedsensors': [], 'allsensors': ['binary_sensor.door_window_sensor_158d000187120a', 'binary_sensor.motion_sensor_158d00016dcfa8', 'binary_sensor.switch_158d000186e9bd']}, 'state': 'armed_home', 'last_changed': '2017-10-06T03:16:04.699603+00:00'}, 'entity_id': 'alarm_control_panel.house', 'new_state': {'last_updated': '2017-10-06T03:16:19.609743+00:00', 'entity_id': 'alarm_control_panel.house', 'attributes': {'friendly_name': 'House', 'immediate': [], 'zones': ['group.zone_downstairs', 'group.zone_garage', 'group.zone_kitchen', 'group.zone_living_room', 'group.zone_outside', 'group.zone_upstairs'], 'changed_by': '', 'ignored': ['binary_sensor.door_window_sensor_158d000187120a', 'binary_sensor.motion_sensor_158d00016dcfa8', 'binary_sensor.switch_158d000186e9bd'], 'bypassedsensors': [], 'code_format': None, 'triggeredBy': "{'name': 'Legendary', 'chat_id': '396287366'}", 'delayed': [], 'changedby': '', 'trippedsensors': [], 'allsensors': ['binary_sensor.door_window_sensor_158d000187120a', 'binary_sensor.motion_sensor_158d00016dcfa8', 'binary_sensor.switch_158d000186e9bd']}, 'state': 'disarmed', 'last_changed': '2017-10-06T03:16:19.609743+00:00'}}, 'name': 'Alarm', 'function': <bound method AlarmReaction.alarmListener of <alarm.AlarmReaction object at 0xb5b306d0>>, 'type': 'event', 'event': 'state_changed', 'kwargs': {'entity_id': 'alarm_control_panel.house'}}
2017-10-06 05:16:20.348376 WARNING ------------------------------------------------------------
2017-10-06 05:16:20.367530 WARNING Traceback (most recent call last):
  File "/srv/homeassistant/lib/python3.4/site-packages/appdaemon/appdaemon.py", line 528, in worker
    function(args["event"], data, args["kwargs"])
  File "/home/homeassistant/config/appdaemon/apps/alarm.py", line 17, in alarmListener
    self.trigger(data,kwargs)
  File "/home/homeassistant/config/appdaemon/apps/alarm.py", line 29, in trigger
    self.telegram_notify(new_state, triggered_by)
  File "/home/homeassistant/config/appdaemon/apps/alarm.py", line 52, in telegram_notify
    keyboard = self.telegram.getKeyboard(new_state,accessgroup)
  File "/home/homeassistant/config/appdaemon/apps/telegram.py", line 373, in getKeyboard
    self.call_service("telegram_bot/send_message",
  File "/home/homeassistant/config/appdaemon/apps/telegram.py", line 381, in getRefinedKeyboard
    self.call_service("homeassistant/turn_off", entity_id = entity_id)
KeyError: 'armStay'

2017-10-06 05:16:20.371493 WARNING ------------------------------------------------------------
2017-10-06 05:16:41.575003 WARNING ------------------------------------------------------------
2017-10-06 05:16:41.578726 WARNING Unexpected error in worker for App Alarm:
2017-10-06 05:16:41.583517 WARNING Worker Ags: {'id': UUID('3917c45f-4371-4d17-9d75-a834abec83bc'), 'data': {'old_state': {'last_updated': '2017-10-06T03:16:33.960314+00:00', 'entity_id': 'alarm_control_panel.house', 'attributes': {'friendly_name': 'House', 'immediate': [], 'zones': ['group.zone_downstairs', 'group.zone_garage', 'group.zone_kitchen', 'group.zone_living_room', 'group.zone_outside', 'group.zone_upstairs'], 'changed_by': '', 'ignored': ['binary_sensor.door_window_sensor_158d000187120a', 'binary_sensor.motion_sensor_158d00016dcfa8', 'binary_sensor.switch_158d000186e9bd'], 'bypassedsensors': ['binary_sensor.door_window_sensor_158d000187120a', 'binary_sensor.motion_sensor_158d00016dcfa8'], 'code_format': None, 'triggeredBy': "{'name': 'Legendary', 'chat_id': '396287366'}", 'delayed': [], 'changedby': '', 'trippedsensors': [], 'allsensors': ['binary_sensor.door_window_sensor_158d000187120a', 'binary_sensor.motion_sensor_158d00016dcfa8', 'binary_sensor.switch_158d000186e9bd']}, 'state': 'disarmed', 'last_changed': '2017-10-06T03:16:19.609743+00:00'}, 'entity_id': 'alarm_control_panel.house', 'new_state': {'last_updated': '2017-10-06T03:16:40.838736+00:00', 'entity_id': 'alarm_control_panel.house', 'attributes': {'friendly_name': 'House', 'immediate': ['binary_sensor.door_window_sensor_158d000187120a'], 'zones': ['group.zone_downstairs', 'group.zone_garage', 'group.zone_kitchen', 'group.zone_living_room', 'group.zone_outside', 'group.zone_upstairs'], 'changed_by': '', 'ignored': ['binary_sensor.motion_sensor_158d00016dcfa8'], 'bypassedsensors': ['binary_sensor.door_window_sensor_158d000187120a', 'binary_sensor.motion_sensor_158d00016dcfa8'], 'code_format': None, 'triggeredBy': "{'name': 'Legendary', 'chat_id': '396287366'}", 'delayed': ['binary_sensor.switch_158d000186e9bd'], 'changedby': '', 'trippedsensors': [], 'allsensors': ['binary_sensor.door_window_sensor_158d000187120a', 'binary_sensor.motion_sensor_158d00016dcfa8', 'binary_sensor.switch_158d000186e9bd']}, 'state': 'armed_home', 'last_changed': '2017-10-06T03:16:40.838736+00:00'}}, 'name': 'Alarm', 'function': <bound method AlarmReaction.alarmListener of <alarm.AlarmReaction object at 0xb5b306d0>>, 'type': 'event', 'event': 'state_changed', 'kwargs': {'entity_id': 'alarm_control_panel.house'}}
2017-10-06 05:16:41.596575 WARNING ------------------------------------------------------------
2017-10-06 05:16:41.607908 WARNING Traceback (most recent call last):
  File "/srv/homeassistant/lib/python3.4/site-packages/appdaemon/appdaemon.py", line 528, in worker
    function(args["event"], data, args["kwargs"])
  File "/home/homeassistant/config/appdaemon/apps/alarm.py", line 17, in alarmListener
    self.trigger(data,kwargs)
  File "/home/homeassistant/config/appdaemon/apps/alarm.py", line 29, in trigger
    self.telegram_notify(new_state, triggered_by)
  File "/home/homeassistant/config/appdaemon/apps/alarm.py", line 52, in telegram_notify
    keyboard = self.telegram.getKeyboard(new_state,accessgroup)
  File "/home/homeassistant/config/appdaemon/apps/telegram.py", line 373, in getKeyboard
    self.call_service("telegram_bot/send_message",
  File "/home/homeassistant/config/appdaemon/apps/telegram.py", line 381, in getRefinedKeyboard
    self.call_service("homeassistant/turn_off", entity_id = entity_id)
KeyError: 'disarm'

2017-10-06 05:16:41.631573 WARNING ------------------------------------------------------------
2017-10-06 05:17:05.936981 WARNING ------------------------------------------------------------
2017-10-06 05:17:05.940569 WARNING Unexpected error in worker for App Alarm:
2017-10-06 05:17:05.967950 WARNING Worker Ags: {'id': UUID('3917c45f-4371-4d17-9d75-a834abec83bc'), 'data': {'old_state': {'last_updated': '2017-10-06T03:16:40.838736+00:00', 'entity_id': 'alarm_control_panel.house', 'attributes': {'friendly_name': 'House', 'immediate': ['binary_sensor.door_window_sensor_158d000187120a'], 'zones': ['group.zone_downstairs', 'group.zone_garage', 'group.zone_kitchen', 'group.zone_living_room', 'group.zone_outside', 'group.zone_upstairs'], 'changed_by': '', 'ignored': ['binary_sensor.motion_sensor_158d00016dcfa8'], 'bypassedsensors': ['binary_sensor.door_window_sensor_158d000187120a', 'binary_sensor.motion_sensor_158d00016dcfa8'], 'code_format': None, 'triggeredBy': "{'name': 'Legendary', 'chat_id': '396287366'}", 'delayed': ['binary_sensor.switch_158d000186e9bd'], 'changedby': '', 'trippedsensors': [], 'allsensors': ['binary_sensor.door_window_sensor_158d000187120a', 'binary_sensor.motion_sensor_158d00016dcfa8', 'binary_sensor.switch_158d000186e9bd']}, 'state': 'armed_home', 'last_changed': '2017-10-06T03:16:40.838736+00:00'}, 'entity_id': 'alarm_control_panel.house', 'new_state': {'last_updated': '2017-10-06T03:17:04.780759+00:00', 'entity_id': 'alarm_control_panel.house', 'attributes': {'friendly_name': 'House', 'immediate': [], 'zones': ['group.zone_downstairs', 'group.zone_garage', 'group.zone_kitchen', 'group.zone_living_room', 'group.zone_outside', 'group.zone_upstairs'], 'changed_by': '', 'ignored': ['binary_sensor.door_window_sensor_158d000187120a', 'binary_sensor.motion_sensor_158d00016dcfa8', 'binary_sensor.switch_158d000186e9bd'], 'bypassedsensors': [], 'code_format': None, 'triggeredBy': "{'name': 'Legendary', 'chat_id': '396287366'}", 'delayed': [], 'changedby': '', 'trippedsensors': [], 'allsensors': ['binary_sensor.door_window_sensor_158d000187120a', 'binary_sensor.motion_sensor_158d00016dcfa8', 'binary_sensor.switch_158d000186e9bd']}, 'state': 'disarmed', 'last_changed': '2017-10-06T03:17:04.780759+00:00'}}, 'name': 'Alarm', 'function': <bound method AlarmReaction.alarmListener of <alarm.AlarmReaction object at 0xb5b306d0>>, 'type': 'event', 'event': 'state_changed', 'kwargs': {'entity_id': 'alarm_control_panel.house'}}
2017-10-06 05:17:05.977633 WARNING ------------------------------------------------------------
2017-10-06 05:17:05.992921 WARNING Traceback (most recent call last):
  File "/srv/homeassistant/lib/python3.4/site-packages/appdaemon/appdaemon.py", line 528, in worker
    function(args["event"], data, args["kwargs"])
  File "/home/homeassistant/config/appdaemon/apps/alarm.py", line 17, in alarmListener
    self.trigger(data,kwargs)
  File "/home/homeassistant/config/appdaemon/apps/alarm.py", line 29, in trigger
    self.telegram_notify(new_state, triggered_by)
  File "/home/homeassistant/config/appdaemon/apps/alarm.py", line 52, in telegram_notify
    keyboard = self.telegram.getKeyboard(new_state,accessgroup)
  File "/home/homeassistant/config/appdaemon/apps/telegram.py", line 373, in getKeyboard
    self.call_service("telegram_bot/send_message",
  File "/home/homeassistant/config/appdaemon/apps/telegram.py", line 381, in getRefinedKeyboard
    self.call_service("homeassistant/turn_off", entity_id = entity_id)
KeyError: 'armStay'

2017-10-06 05:17:06.086582 WARNING ------------------------------------------------------------
2017-10-06 05:18:23.689931 WARNING ------------------------------------------------------------
2017-10-06 05:18:23.703081 WARNING Unexpected error in worker for App Alarm:
2017-10-06 05:18:23.715734 WARNING Worker Ags: {'id': UUID('3917c45f-4371-4d17-9d75-a834abec83bc'), 'data': {'old_state': {'last_updated': '2017-10-06T03:17:28.906668+00:00', 'entity_id': 'alarm_control_panel.house', 'attributes': {'friendly_name': 'House', 'immediate': [], 'zones': ['group.zone_downstairs', 'group.zone_garage', 'group.zone_kitchen', 'group.zone_living_room', 'group.zone_outside', 'group.zone_upstairs'], 'changed_by': '', 'ignored': ['binary_sensor.door_window_sensor_158d000187120a', 'binary_sensor.motion_sensor_158d00016dcfa8', 'binary_sensor.switch_158d000186e9bd'], 'bypassedsensors': ['binary_sensor.switch_158d000186e9bd'], 'code_format': None, 'triggeredBy': "{'name': 'Legendary', 'chat_id': '396287366'}", 'delayed': [], 'changedby': '', 'trippedsensors': [], 'allsensors': ['binary_sensor.door_window_sensor_158d000187120a', 'binary_sensor.motion_sensor_158d00016dcfa8', 'binary_sensor.switch_158d000186e9bd']}, 'state': 'disarmed', 'last_changed': '2017-10-06T03:17:04.780759+00:00'}, 'entity_id': 'alarm_control_panel.house', 'new_state': {'last_updated': '2017-10-06T03:18:22.483159+00:00', 'entity_id': 'alarm_control_panel.house', 'attributes': {'friendly_name': 'House', 'immediate': ['binary_sensor.door_window_sensor_158d000187120a'], 'zones': ['group.zone_downstairs', 'group.zone_garage', 'group.zone_kitchen', 'group.zone_living_room', 'group.zone_outside', 'group.zone_upstairs'], 'changed_by': '', 'ignored': ['binary_sensor.motion_sensor_158d00016dcfa8'], 'bypassedsensors': ['binary_sensor.switch_158d000186e9bd'], 'code_format': None, 'triggeredBy': "{'name': 'Legendary', 'chat_id': '396287366'}", 'delayed': ['binary_sensor.switch_158d000186e9bd'], 'changedby': '', 'trippedsensors': [], 'allsensors': ['binary_sensor.door_window_sensor_158d000187120a', 'binary_sensor.motion_sensor_158d00016dcfa8', 'binary_sensor.switch_158d000186e9bd']}, 'state': 'armed_home', 'last_changed': '2017-10-06T03:18:22.483159+00:00'}}, 'name': 'Alarm', 'function': <bound method AlarmReaction.alarmListener of <alarm.AlarmReaction object at 0xb5b306d0>>, 'type': 'event', 'event': 'state_changed', 'kwargs': {'entity_id': 'alarm_control_panel.house'}}
2017-10-06 05:18:23.734749 WARNING ------------------------------------------------------------
2017-10-06 05:18:23.747475 WARNING Traceback (most recent call last):
  File "/srv/homeassistant/lib/python3.4/site-packages/appdaemon/appdaemon.py", line 528, in worker
    function(args["event"], data, args["kwargs"])
  File "/home/homeassistant/config/appdaemon/apps/alarm.py", line 17, in alarmListener
    self.trigger(data,kwargs)
  File "/home/homeassistant/config/appdaemon/apps/alarm.py", line 29, in trigger
    self.telegram_notify(new_state, triggered_by)
  File "/home/homeassistant/config/appdaemon/apps/alarm.py", line 52, in telegram_notify
    keyboard = self.telegram.getKeyboard(new_state,accessgroup)
  File "/home/homeassistant/config/appdaemon/apps/telegram.py", line 373, in getKeyboard
    self.call_service("telegram_bot/send_message",
  File "/home/homeassistant/config/appdaemon/apps/telegram.py", line 381, in getRefinedKeyboard
    self.call_service("homeassistant/turn_off", entity_id = entity_id)
KeyError: 'disarm'

2017-10-06 05:18:23.757200 WARNING ------------------------------------------------------------
2017-10-06 23:19:18.331599 WARNING ------------------------------------------------------------
2017-10-06 23:19:18.348198 WARNING Unexpected error during loading of telegram.py:
2017-10-06 23:19:18.353306 WARNING ------------------------------------------------------------
2017-10-06 23:19:18.371057 WARNING Traceback (most recent call last):
  File "/srv/homeassistant/lib/python3.4/site-packages/appdaemon/appdaemon.py", line 903, in read_app
    importlib.reload(conf.modules[module_name])
  File "/srv/homeassistant/lib/python3.4/importlib/__init__.py", line 149, in reload
    methods.exec(module)
  File "<frozen importlib._bootstrap>", line 1153, in exec
  File "<frozen importlib._bootstrap>", line 1129, in _exec
  File "<frozen importlib._bootstrap>", line 1467, in exec_module
  File "<frozen importlib._bootstrap>", line 1572, in get_code
  File "<frozen importlib._bootstrap>", line 1532, in source_to_code
  File "<frozen importlib._bootstrap>", line 321, in _call_with_frames_removed
  File "/home/homeassistant/config/appdaemon/apps/telegram.py", line 390
    friendly_name_temp = str(self.get_state(entity,"telegram_name"))
                                                                   ^
TabError: inconsistent use of tabs and spaces in indentation

2017-10-06 23:19:18.374576 WARNING ------------------------------------------------------------
2017-10-06 23:19:19.338882 WARNING ------------------------------------------------------------
2017-10-06 23:19:19.342399 WARNING Unexpected error during loading of telegram.py:
2017-10-06 23:19:19.347887 WARNING ------------------------------------------------------------
2017-10-06 23:19:19.356638 WARNING Traceback (most recent call last):
  File "/srv/homeassistant/lib/python3.4/site-packages/appdaemon/appdaemon.py", line 903, in read_app
    importlib.reload(conf.modules[module_name])
  File "/srv/homeassistant/lib/python3.4/importlib/__init__.py", line 149, in reload
    methods.exec(module)
  File "<frozen importlib._bootstrap>", line 1153, in exec
  File "<frozen importlib._bootstrap>", line 1129, in _exec
  File "<frozen importlib._bootstrap>", line 1467, in exec_module
  File "<frozen importlib._bootstrap>", line 1572, in get_code
  File "<frozen importlib._bootstrap>", line 1532, in source_to_code
  File "<frozen importlib._bootstrap>", line 321, in _call_with_frames_removed
  File "/home/homeassistant/config/appdaemon/apps/telegram.py", line 390
    friendly_name_temp = str(self.get_state(entity,"telegram_name"))
                                                                   ^
TabError: inconsistent use of tabs and spaces in indentation

2017-10-06 23:19:19.361609 WARNING ------------------------------------------------------------
2017-10-06 23:19:39.384610 WARNING ------------------------------------------------------------
2017-10-06 23:19:39.388733 WARNING Unexpected error during loading of telegram.py:
2017-10-06 23:19:39.393925 WARNING ------------------------------------------------------------
2017-10-06 23:19:39.402568 WARNING Traceback (most recent call last):
  File "/srv/homeassistant/lib/python3.4/site-packages/appdaemon/appdaemon.py", line 903, in read_app
    importlib.reload(conf.modules[module_name])
  File "/srv/homeassistant/lib/python3.4/importlib/__init__.py", line 149, in reload
    methods.exec(module)
  File "<frozen importlib._bootstrap>", line 1153, in exec
  File "<frozen importlib._bootstrap>", line 1129, in _exec
  File "<frozen importlib._bootstrap>", line 1467, in exec_module
  File "<frozen importlib._bootstrap>", line 1572, in get_code
  File "<frozen importlib._bootstrap>", line 1532, in source_to_code
  File "<frozen importlib._bootstrap>", line 321, in _call_with_frames_removed
  File "/home/homeassistant/config/appdaemon/apps/telegram.py", line 390
    friendly_name_temp = str(self.get_state(entity,"telegram_name"))
                                                                   ^
TabError: inconsistent use of tabs and spaces in indentation

2017-10-06 23:19:39.407033 WARNING ------------------------------------------------------------
2017-10-06 23:20:43.340266 WARNING ------------------------------------------------------------
2017-10-06 23:20:43.355312 WARNING Unexpected error during loading of telegram.py:
2017-10-06 23:20:43.359714 WARNING ------------------------------------------------------------
2017-10-06 23:20:43.376310 WARNING Traceback (most recent call last):
  File "/srv/homeassistant/lib/python3.4/site-packages/appdaemon/appdaemon.py", line 903, in read_app
    importlib.reload(conf.modules[module_name])
  File "/srv/homeassistant/lib/python3.4/importlib/__init__.py", line 149, in reload
    methods.exec(module)
  File "<frozen importlib._bootstrap>", line 1153, in exec
  File "<frozen importlib._bootstrap>", line 1129, in _exec
  File "<frozen importlib._bootstrap>", line 1467, in exec_module
  File "<frozen importlib._bootstrap>", line 1572, in get_code
  File "<frozen importlib._bootstrap>", line 1532, in source_to_code
  File "<frozen importlib._bootstrap>", line 321, in _call_with_frames_removed
  File "/home/homeassistant/config/appdaemon/apps/telegram.py", line 399
    friendly_name_temp = str(self.get_state(entity,"telegram_name"))
                                                                   ^
TabError: inconsistent use of tabs and spaces in indentation

2017-10-06 23:20:43.382016 WARNING ------------------------------------------------------------
2017-10-06 23:20:54.334482 WARNING ------------------------------------------------------------
2017-10-06 23:20:54.345975 WARNING Unexpected error during loading of telegram.py:
2017-10-06 23:20:54.350093 WARNING ------------------------------------------------------------
2017-10-06 23:20:54.369904 WARNING Traceback (most recent call last):
  File "/srv/homeassistant/lib/python3.4/site-packages/appdaemon/appdaemon.py", line 903, in read_app
    importlib.reload(conf.modules[module_name])
  File "/srv/homeassistant/lib/python3.4/importlib/__init__.py", line 149, in reload
    methods.exec(module)
  File "<frozen importlib._bootstrap>", line 1153, in exec
  File "<frozen importlib._bootstrap>", line 1129, in _exec
  File "<frozen importlib._bootstrap>", line 1467, in exec_module
  File "<frozen importlib._bootstrap>", line 1572, in get_code
  File "<frozen importlib._bootstrap>", line 1532, in source_to_code
  File "<frozen importlib._bootstrap>", line 321, in _call_with_frames_removed
  File "/home/homeassistant/config/appdaemon/apps/telegram.py", line 406
    friendly_name_temp = str(self.get_state(entity,"telegram_name"))
                                                                   ^
TabError: inconsistent use of tabs and spaces in indentation

2017-10-06 23:20:54.377639 WARNING ------------------------------------------------------------
2017-10-06 23:23:40.349354 WARNING ------------------------------------------------------------
2017-10-06 23:23:40.357584 WARNING Unexpected error during loading of telegram.py:
2017-10-06 23:23:40.365225 WARNING ------------------------------------------------------------
2017-10-06 23:23:40.375665 WARNING Traceback (most recent call last):
  File "/srv/homeassistant/lib/python3.4/site-packages/appdaemon/appdaemon.py", line 903, in read_app
    importlib.reload(conf.modules[module_name])
  File "/srv/homeassistant/lib/python3.4/importlib/__init__.py", line 149, in reload
    methods.exec(module)
  File "<frozen importlib._bootstrap>", line 1153, in exec
  File "<frozen importlib._bootstrap>", line 1129, in _exec
  File "<frozen importlib._bootstrap>", line 1467, in exec_module
  File "<frozen importlib._bootstrap>", line 1572, in get_code
  File "<frozen importlib._bootstrap>", line 1532, in source_to_code
  File "<frozen importlib._bootstrap>", line 321, in _call_with_frames_removed
  File "/home/homeassistant/config/appdaemon/apps/telegram.py", line 392
    if friendly_name_temp is 'None':
                                   ^
SyntaxError: invalid syntax

2017-10-06 23:23:40.395227 WARNING ------------------------------------------------------------
2017-10-06 23:23:51.724296 WARNING ------------------------------------------------------------
2017-10-06 23:23:51.745256 WARNING Unexpected error in worker for App Telegram:
2017-10-06 23:23:51.749190 WARNING Worker Ags: {'type': 'event', 'event': 'telegram_text', 'data': {'user_id': 396287366, 'chat_id': 396287366, 'from_first': 'Legendary', 'from_last': 'Dav', 'text': 'Lights'}, 'name': 'Telegram', 'function': <bound method TelegramBotEventListener.receive_telegram_text of <telegram.TelegramBotEventListener object at 0xb56e6070>>, 'kwargs': {}, 'id': UUID('704b1178-b293-4df4-8461-11af5164c303')}
2017-10-06 23:23:51.765241 WARNING ------------------------------------------------------------
2017-10-06 23:23:51.829103 WARNING Traceback (most recent call last):
  File "/srv/homeassistant/lib/python3.4/site-packages/appdaemon/appdaemon.py", line 528, in worker
    function(args["event"], data, args["kwargs"])
  File "/home/homeassistant/config/appdaemon/apps/telegram.py", line 102, in receive_telegram_text
    simpleFunction(self, payload_event, accessgroup)
  File "/home/homeassistant/config/appdaemon/apps/telegram.py", line 440, in control_lights
    keyboard = self.getKeyboard("lights",accessgroup,payload_event))
  File "/home/homeassistant/config/appdaemon/apps/telegram.py", line 391, in getKeyboard
    self.log(type(friendly_name_temp))
  File "/srv/homeassistant/lib/python3.4/site-packages/appdaemon/appapi.py", line 172, in log
    msg = self._sub_stack(msg)
  File "/srv/homeassistant/lib/python3.4/site-packages/appdaemon/appapi.py", line 150, in _sub_stack
    msg = json.dumps(msg)
  File "/usr/lib/python3.4/json/__init__.py", line 230, in dumps
    return _default_encoder.encode(obj)
  File "/usr/lib/python3.4/json/encoder.py", line 192, in encode
    chunks = self.iterencode(o, _one_shot=True)
  File "/usr/lib/python3.4/json/encoder.py", line 250, in iterencode
    return _iterencode(o, 0)
  File "/usr/lib/python3.4/json/encoder.py", line 173, in default
    raise TypeError(repr(o) + " is not JSON serializable")
TypeError: <class 'str'> is not JSON serializable

2017-10-06 23:23:51.842112 WARNING ------------------------------------------------------------
2017-10-06 23:30:34.325528 WARNING ------------------------------------------------------------
2017-10-06 23:30:34.335826 WARNING Unexpected error during loading of telegram.py:
2017-10-06 23:30:34.339892 WARNING ------------------------------------------------------------
2017-10-06 23:30:34.364996 WARNING Traceback (most recent call last):
  File "/srv/homeassistant/lib/python3.4/site-packages/appdaemon/appdaemon.py", line 903, in read_app
    importlib.reload(conf.modules[module_name])
  File "/srv/homeassistant/lib/python3.4/importlib/__init__.py", line 149, in reload
    methods.exec(module)
  File "<frozen importlib._bootstrap>", line 1153, in exec
  File "<frozen importlib._bootstrap>", line 1129, in _exec
  File "<frozen importlib._bootstrap>", line 1467, in exec_module
  File "<frozen importlib._bootstrap>", line 1572, in get_code
  File "<frozen importlib._bootstrap>", line 1532, in source_to_code
  File "<frozen importlib._bootstrap>", line 321, in _call_with_frames_removed
  File "/home/homeassistant/config/appdaemon/apps/telegram.py", line 366
    friendly_name_temp = self.get_state(entity,"telegram_name")
                                                              ^
TabError: inconsistent use of tabs and spaces in indentation

2017-10-06 23:30:34.368879 WARNING ------------------------------------------------------------
2017-10-06 23:30:35.324210 WARNING ------------------------------------------------------------
2017-10-06 23:30:35.333306 WARNING Unexpected error during loading of telegram.py:
2017-10-06 23:30:35.341481 WARNING ------------------------------------------------------------
2017-10-06 23:30:35.355810 WARNING Traceback (most recent call last):
  File "/srv/homeassistant/lib/python3.4/site-packages/appdaemon/appdaemon.py", line 903, in read_app
    importlib.reload(conf.modules[module_name])
  File "/srv/homeassistant/lib/python3.4/importlib/__init__.py", line 149, in reload
    methods.exec(module)
  File "<frozen importlib._bootstrap>", line 1153, in exec
  File "<frozen importlib._bootstrap>", line 1129, in _exec
  File "<frozen importlib._bootstrap>", line 1467, in exec_module
  File "<frozen importlib._bootstrap>", line 1572, in get_code
  File "<frozen importlib._bootstrap>", line 1532, in source_to_code
  File "<frozen importlib._bootstrap>", line 321, in _call_with_frames_removed
  File "/home/homeassistant/config/appdaemon/apps/telegram.py", line 366
    friendly_name_temp = self.get_state(entity,"telegram_name")
                                                              ^
TabError: inconsistent use of tabs and spaces in indentation

2017-10-06 23:30:35.375358 WARNING ------------------------------------------------------------
2017-10-06 23:36:21.331616 WARNING ------------------------------------------------------------
2017-10-06 23:36:21.346748 WARNING Unexpected error during loading of telegram.py:
2017-10-06 23:36:21.355016 WARNING ------------------------------------------------------------
2017-10-06 23:36:21.360413 WARNING Traceback (most recent call last):
  File "/srv/homeassistant/lib/python3.4/site-packages/appdaemon/appdaemon.py", line 903, in read_app
    importlib.reload(conf.modules[module_name])
  File "/srv/homeassistant/lib/python3.4/importlib/__init__.py", line 149, in reload
    methods.exec(module)
  File "<frozen importlib._bootstrap>", line 1153, in exec
  File "<frozen importlib._bootstrap>", line 1129, in _exec
  File "<frozen importlib._bootstrap>", line 1467, in exec_module
  File "<frozen importlib._bootstrap>", line 1572, in get_code
  File "<frozen importlib._bootstrap>", line 1532, in source_to_code
  File "<frozen importlib._bootstrap>", line 321, in _call_with_frames_removed
  File "/home/homeassistant/config/appdaemon/apps/telegram.py", line 355
    friendly_name_temp = str(friendly_name_temp).lower()
                                                       ^
TabError: inconsistent use of tabs and spaces in indentation

2017-10-06 23:36:21.363109 WARNING ------------------------------------------------------------
2017-10-06 23:36:44.331303 WARNING ------------------------------------------------------------
2017-10-06 23:36:44.345203 WARNING Unexpected error during loading of telegram.py:
2017-10-06 23:36:44.349051 WARNING ------------------------------------------------------------
2017-10-06 23:36:44.361645 WARNING Traceback (most recent call last):
  File "/srv/homeassistant/lib/python3.4/site-packages/appdaemon/appdaemon.py", line 903, in read_app
    importlib.reload(conf.modules[module_name])
  File "/srv/homeassistant/lib/python3.4/importlib/__init__.py", line 149, in reload
    methods.exec(module)
  File "<frozen importlib._bootstrap>", line 1153, in exec
  File "<frozen importlib._bootstrap>", line 1129, in _exec
  File "<frozen importlib._bootstrap>", line 1467, in exec_module
  File "<frozen importlib._bootstrap>", line 1572, in get_code
  File "<frozen importlib._bootstrap>", line 1532, in source_to_code
  File "<frozen importlib._bootstrap>", line 321, in _call_with_frames_removed
  File "/home/homeassistant/config/appdaemon/apps/telegram.py", line 373
    friendly_name_temp = str(friendly_name_temp).lower()
                                                       ^
TabError: inconsistent use of tabs and spaces in indentation

2017-10-06 23:36:44.375219 WARNING ------------------------------------------------------------
2017-10-06 23:51:21.363595 WARNING ------------------------------------------------------------
2017-10-06 23:51:21.375843 WARNING Unexpected error during loading of telegram.py:
2017-10-06 23:51:21.380015 WARNING ------------------------------------------------------------
2017-10-06 23:51:21.395366 WARNING Traceback (most recent call last):
  File "/srv/homeassistant/lib/python3.4/site-packages/appdaemon/appdaemon.py", line 903, in read_app
    importlib.reload(conf.modules[module_name])
  File "/srv/homeassistant/lib/python3.4/importlib/__init__.py", line 149, in reload
    methods.exec(module)
  File "<frozen importlib._bootstrap>", line 1153, in exec
  File "<frozen importlib._bootstrap>", line 1129, in _exec
  File "<frozen importlib._bootstrap>", line 1467, in exec_module
  File "<frozen importlib._bootstrap>", line 1572, in get_code
  File "<frozen importlib._bootstrap>", line 1532, in source_to_code
  File "<frozen importlib._bootstrap>", line 321, in _call_with_frames_removed
  File "/home/homeassistant/config/appdaemon/apps/telegram.py", line 461
    self.log("Serving Camera Menu")
                                  ^
TabError: inconsistent use of tabs and spaces in indentation

2017-10-06 23:51:21.406300 WARNING ------------------------------------------------------------
2017-10-06 23:51:22.339647 WARNING ------------------------------------------------------------
2017-10-06 23:51:22.352258 WARNING Unexpected error during loading of telegram.py:
2017-10-06 23:51:22.355790 WARNING ------------------------------------------------------------
2017-10-06 23:51:22.376065 WARNING Traceback (most recent call last):
  File "/srv/homeassistant/lib/python3.4/site-packages/appdaemon/appdaemon.py", line 903, in read_app
    importlib.reload(conf.modules[module_name])
  File "/srv/homeassistant/lib/python3.4/importlib/__init__.py", line 149, in reload
    methods.exec(module)
  File "<frozen importlib._bootstrap>", line 1153, in exec
  File "<frozen importlib._bootstrap>", line 1129, in _exec
  File "<frozen importlib._bootstrap>", line 1467, in exec_module
  File "<frozen importlib._bootstrap>", line 1572, in get_code
  File "<frozen importlib._bootstrap>", line 1532, in source_to_code
  File "<frozen importlib._bootstrap>", line 321, in _call_with_frames_removed
  File "/home/homeassistant/config/appdaemon/apps/telegram.py", line 461
    self.log("Serving Camera Menu")
                                  ^
TabError: inconsistent use of tabs and spaces in indentation

2017-10-06 23:51:22.385065 WARNING ------------------------------------------------------------
2017-10-06 23:52:04.339921 WARNING ------------------------------------------------------------
2017-10-06 23:52:04.347911 WARNING Unexpected error during loading of telegram.py:
2017-10-06 23:52:04.355470 WARNING ------------------------------------------------------------
2017-10-06 23:52:04.365656 WARNING Traceback (most recent call last):
  File "/srv/homeassistant/lib/python3.4/site-packages/appdaemon/appdaemon.py", line 903, in read_app
    importlib.reload(conf.modules[module_name])
  File "/srv/homeassistant/lib/python3.4/importlib/__init__.py", line 149, in reload
    methods.exec(module)
  File "<frozen importlib._bootstrap>", line 1153, in exec
  File "<frozen importlib._bootstrap>", line 1129, in _exec
  File "<frozen importlib._bootstrap>", line 1467, in exec_module
  File "<frozen importlib._bootstrap>", line 1572, in get_code
  File "<frozen importlib._bootstrap>", line 1532, in source_to_code
  File "<frozen importlib._bootstrap>", line 321, in _call_with_frames_removed
  File "/home/homeassistant/config/appdaemon/apps/telegram.py", line 466
    self.log("+---}")
       ^
SyntaxError: invalid syntax

2017-10-06 23:52:04.385233 WARNING ------------------------------------------------------------
2017-10-06 23:52:05.337676 WARNING ------------------------------------------------------------
2017-10-06 23:52:05.345585 WARNING Unexpected error during loading of telegram.py:
2017-10-06 23:52:05.357698 WARNING ------------------------------------------------------------
2017-10-06 23:52:05.363226 WARNING Traceback (most recent call last):
  File "/srv/homeassistant/lib/python3.4/site-packages/appdaemon/appdaemon.py", line 903, in read_app
    importlib.reload(conf.modules[module_name])
  File "/srv/homeassistant/lib/python3.4/importlib/__init__.py", line 149, in reload
    methods.exec(module)
  File "<frozen importlib._bootstrap>", line 1153, in exec
  File "<frozen importlib._bootstrap>", line 1129, in _exec
  File "<frozen importlib._bootstrap>", line 1467, in exec_module
  File "<frozen importlib._bootstrap>", line 1572, in get_code
  File "<frozen importlib._bootstrap>", line 1532, in source_to_code
  File "<frozen importlib._bootstrap>", line 321, in _call_with_frames_removed
  File "/home/homeassistant/config/appdaemon/apps/telegram.py", line 466
    self.log("+---}")
       ^
SyntaxError: invalid syntax

2017-10-06 23:52:05.376695 WARNING ------------------------------------------------------------
